Workbook

Sheet Sheet2
A1: 원보험사코드 | B1: 원수사명 | C1: 티커 | D1: 생손보여부 | E1: 항목번호 | F1: 항목명 | G1: 공시분기 | H1: 사망보험 | I1: 건강보험 | J1: 연금저축보험
B2: 미래에셋생명 | D2: 생명보험 | E2: 1 | F2: 기초 CSM | G2: 2025.1Q | H2: =부문별!I9 -> 785941 | I2: =부문별!I35 -> 883688 | J2: =부문별!I61 -> 239327 | K2: =부문별!I87 -> 168607 | L2: =부문별!I113 -> 649
B3: 미래에셋생명 | D3: 생명보험 | E3: 2 | F3: 신계약 CSM | G3: 2025.1Q | H3: =부문별!I12 -> 10269 | I3: =부문별!I38 -> 115167 | J3: =부문별!I64 -> 8234 | K3: =부문별!I90 -> 7369 | L3: =N(부문별!I116) -> 0
B4: 미래에셋생명 | D4: 생명보험 | E4: 3 | F4: 이자 부리 | G4: 2025.1Q | H4: =부문별!I20 -> 4948 | I4: =부문별!I46 -> 8230 | J4: =부문별!I72 -> 1380 | K4: =부문별!I98 -> 142 | L4: =부문별!I124 -> 4
B5: 미래에셋생명 | D5: 생명보험 | E5: 4 | F5: 가정 및 경험 조정 등 | G5: 2025.1Q | H5: =H7-H6-H4-H3-H2 -> -62318 | I5: =I7-I6-I4-I3-I2 -> -36386 | J5: =J7-J6-J4-J3-J2 -> -14622 | K5: =K7-K6-K4-K3-K2 -> 12456 | L5: =L7-L6-L4-L3-L2 -> 15
B6: 미래에셋생명 | D6: 생명보험 | E6: 5 | F6: CSM 상각 | G6: 2025.1Q | H6: =부문별!I13 -> -14783 | I6: =부문별!I39 -> -19426 | J6: =부문별!I65 -> -7634 | K6: =부문별!I91 -> -6516 | L6: =부문별!I117 -> -14
B7: 미래에셋생명 | D7: 생명보험 | E7: 6 | F7: 기말 CSM | G7: 2025.1Q | H7: =부문별!I25 -> 724057 | I7: =부문별!I51 -> 951273 | J7: =부문별!I77 -> 226685 | K7: =부문별!I103 -> 182058 | L7: =부문별!I129 -> 654
J24: =부문별!I83 -> 소계
J25: =부문별!I86 -> 168607
J26: =부문별!I94 -> -
J27: =K3-K2-J26-J25-J24 -> #VALUE!

Sheet 부문별
A1: i) 사망
A2: (단위: 백만원)
A3: 구분 | D3: 보험료배분접근법 외 보험계약 | J3: 합계
D4: 미래현금흐름의 | E4: 비금융위험에 | F4: 보험계약마진
D5: 현재가치 추정치 | E5: 대한 위험조정 | F5: 전환 시점에 존재했던 보험계약 중 수정소급법을 적용한 보험계약 | G5: 전환 시점에 존재했던 보험계약 중 공정가치법을 적용한 보험계약 | H5: 그 밖의 모든 | I5: 소계
H6: 보험계약
A7: 당분기 | B7: 기초 | C7: 보험계약자산 | D7: - | E7: - | F7: - | G7: - | H7: - | I7: - | J7: -
C8: 보험계약부채 | D8: 5432747 | E8: 165905 | F8: 254672 | G8: 332140 | H8: 199128 | I8: 785941 | J8: 6384593
C9: 기초 잔액 | D9: 5432747 | E9: 165905 | F9: 254672 | G9: 332140 | H9: 199128 | I9: 785941 | J9: 6384593
B10: 미래서비스와관련된 변동분 | C10: 보험계약마진을 조정하는 변동 | D10: 63014 | E10: -696 | F10: -606 | G10: -64773 | H10: 3060 | I10: -62318 | J10: -
C11: 보험계약마진을 조정하지 않는 변동 | D11: 3392 | E11: -37 | F11: - | G11: - | H11: - | I11: - | J11: 3355
C12: 처음 인식한 계약의 효과 | D12: -11184 | E12: 1065 | F12: - | G12: - | H12: 10269 | I12: 10269 | J12: 150
B13: 현행서비스와 관련된 변동분 | C13: 보험계약마진의 당기인식분 | D13: - | E13: - | F13: -4575 | G13: -5258 | H13: -4949 | I13: -14783 | J13: -14783
C14: 위험조정 변동분 | D14: - | E14: -3777 | F14: - | G14: - | H14: - | I14: - | J14: -3777
C15: 경험조정 | D15: -4504 | E15: - | F15: - | G15: - | H15: - | I15: - | J15: -4504
B16: 과거서비스와 관련된 변동분 | C16: 발생사고요소와 관련된 이행현금흐름의변동분 | D16: 1777 | E16: -578 | F16: - | G16: - | H16: - | I16: - | J16: 1199
B17: 현금흐름 | C17: 수취한 보험료 | D17: 311028 | E17: - | F17: - | G17: - | H17: - | I17: - | J17: 311028
C18: 보험취득현금흐름 지급 | D18: -39203 | E18: - | F18: - | G18: - | H18: - | I18: - | J18: -39203
C19: 보험금(투자요소 포함) 및 기타 보험서비스비용의 지급 | D19: -192025 | E19: - | F19: - | G19: - | H19: - | I19: - | J19: -192025
B20: 보험금융손익 | C20: 당기손익인식 보험금융손익 | D20: 20546 | E20: 1091 | F20: 1078 | G20: 2058 | H20: 1812 | I20: 4948 | J20: 26585
C21: 기타포괄손익인식 보험금융손익 | D21: 291461 | E21: -6540 | F21: - | G21: - | H21: - | I21: - | J21: 284921
B22: 기타증감 | D22: -5632 | E22: - | F22: - | G22: - | H22: - | I22: - | J22: -5632
B23: 기말 | C23: 보험계약자산 | D23: - | E23: - | F23: - | G23: - | H23: - | I23: - | J23: -
C24: 보험계약부채 | D24: 5871417 | E24: 156433 | F24: 250570 | G24: 264168 | H24: 209319 | I24: 724057 | J24: 6751907
C25: 기말 잔액 | D25: 5871417 | E25: 156433 | F25: 250570 | G25: 264168 | H25: 209319 | I25: 724057 | J25: 6751907
A27: ii) 건강
A28: (단위: 백만원)
A29: 구분 | D29: 보험료배분접근법 외 보험계약 | J29: 합계
D30: 미래현금흐름의 | E30: 비금융위험에 | F30: 보험계약마진
D31: 현재가치 추정치 | E31: 대한 위험조정 | F31: 전환 시점에 존재했던 보험계약 중 수정소급법을 적용한 보험계약 | G31: 전환 시점에 존재했던 보험계약 중 공정가치법을 적용한 보험계약 | H31: 그 밖의 모든 | I31: 소계
H32: 보험계약
A33: 당분기 | B33: 기초 | C33: 보험계약자산 | D33: - | E33: - | F33: - | G33: - | H33: - | I33: - | J33: -
C34: 보험계약부채 | D34: 2726072 | E34: 141890 | F34: 141225 | G34: 267009 | H34: 475453 | I34: 883688 | J34: 3751650
C35: 기초 잔액 | D35: 2726072 | E35: 141890 | F35: 141225 | G35: 267009 | H35: 475453 | I35: 883688 | J35: 3751650
B36: 미래서비스와 관련된 변동분 | C36: 보험계약마진을 조정하는 변동 | D36: 37258 | E36: -872 | F36: -4719 | G36: 10297 | H36: -41964 | I36: -36386 | J36: -
C37: 보험계약마진을 조정하지 않는 변동 | D37: -5727 | E37: 134 | F37: - | G37: - | H37: - | I37: - | J37: -5593
C38: 처음 인식한 계약의 효과 | D38: -128639 | E38: 14053 | F38: - | G38: - | H38: 115167 | I38: 115167 | J38: 581
B39: 현행서비스와 관련된 변동분 | C39: 보험계약마진의 당기인식분 | D39: - | E39: - | F39: -2638 | G39: -5780 | H39: -11008 | I39: -19426 | J39: -19426
C40: 위험조정 변동분 | D40: - | E40: -2816 | F40: - | G40: - | H40: - | I40: - | J40: -2816
C41: 경험조정 | D41: -3370 | E41: - | F41: - | G41: - | H41: - | I41: - | J41: -3370
...
