Workbook

Sheet Sheet1
A1: 원보험사코드 | B1: 원수사명 | C1: 티커 | D1: 생손보여부 | E1: 항목번호 | F1: 항목명 | G1: 공시분기 | H1: 값 | I1: 검증
A2: KR1000 | B2: 코리안리 | D2: 손해보험 | E2: 1 | F2: 보험손익 | G2: 2025.2Q | H2: =H3+H14+H25+H26-H28 -> 159685.54 | I2: =ABS(ROUND(H2,0)-159686.803902 )<2 -> TRUE
A3: KR1000 | B3: 코리안리 | D3: 손해보험 | E3: =E2+1 -> 2 | F3: 생명재보험 손익 | G3: 2025.2Q | H3: =H4+H9 -> 61871
A4: KR1000 | B4: 코리안리 | D4: 손해보험 | E4: =E3+1 -> 3 | F4: 생명재보험 수재손익 | G4: 2025.2Q | H4: =보험손익!F14-보험손익!F34 -> 62688
A5: KR1000 | B5: 코리안리 | D5: 손해보험 | E5: =E4+1 -> 4 | F5: 수재 CSM상각 | G5: 2025.2Q | H5: =보험손익!F20 -> 20330
A6: KR1000 | B6: 코리안리 | D6: 손해보험 | E6: =E5+1 -> 5 | F6: 수재 위험조정 변동 | G6: 2025.2Q | H6: =보험손익!F19 -> 8435
A7: KR1000 | B7: 코리안리 | D7: 손해보험 | E7: =E6+1 -> 6 | F7: 수재 예실차 | G7: 2025.2Q | H7: =보험손익!F15+보험손익!F16+보험손익!F17+보험손익!F18-보험손익!F35-보험손익!F36-보험손익!F37 -> -44982
A8: KR1000 | B8: 코리안리 | D8: 손해보험 | E8: =E7+1 -> 7 | F8: 기타 생명재보험 수재손익 | G8: 2025.2Q | H8: =H4-SUM(H5:H7) -> 78905
A9: KR1000 | B9: 코리안리 | D9: 손해보험 | E9: =E8+1 -> 8 | F9: 생명재보험 출재손익 | G9: 2025.2Q | H9: =보험손익!F56-보험손익!F72 -> -817
A10: KR1000 | B10: 코리안리 | D10: 손해보험 | E10: =E9+1 -> 9 | F10: 출재 CSM상각 | G10: 2025.2Q | H10: =-보험손익!F76 -> 5502
A11: KR1000 | B11: 코리안리 | D11: 손해보험 | E11: =E10+1 -> 10 | F11: 출재 위험조정 변동 | G11: 2025.2Q | H11: =-보험손익!F75 -> -350
A12: KR1000 | B12: 코리안리 | D12: 손해보험 | E12: =E11+1 -> 11 | F12: 출재 예실차 | G12: 2025.2Q | H12: =보험손익!F57-보험손익!F73-보험손익!F74 -> 13600
A13: KR1000 | B13: 코리안리 | D13: 손해보험 | E13: =E12+1 -> 12 | F13: 기타 생명재보험 출재손익 | G13: 2025.2Q | H13: =H9-SUM(H10:H12) -> -19569
A14: KR1000 | B14: 코리안리 | D14: 손해보험 | E14: =E3&"-1" -> 2-1 | F14: 장기재보험 손익 | G14: 2025.2Q | H14: =H15+H20 -> 2721
A15: KR1000 | B15: 코리안리 | D15: 손해보험 | E15: =E4&"-1" -> 3-1 | F15: 장기재보험 수재손익 | G15: 2025.2Q | H15: =보험손익!D14-보험손익!D34 -> -15376
A16: KR1000 | B16: 코리안리 | D16: 손해보험 | E16: =E5&"-1" -> 4-1 | F16: 수재 CSM상각 | G16: 2025.2Q | H16: =보험손익!D20 -> 16529
A17: KR1000 | B17: 코리안리 | D17: 손해보험 | E17: =E6&"-1" -> 5-1 | F17: 수재 위험조정 변동 | G17: 2025.2Q | H17: =보험손익!D19 -> 6289
A18: KR1000 | B18: 코리안리 | D18: 손해보험 | E18: =E7&"-1" -> 6-1 | F18: 수재 예실차 | G18: 2025.2Q | H18: =보험손익!D15+보험손익!D16+보험손익!D17+보험손익!D18-보험손익!D35-보험손익!D36-보험손익!D37 -> 10431
A19: KR1000 | B19: 코리안리 | D19: 손해보험 | E19: =E8&"-1" -> 7-1 | F19: 기타 장기재보험 수재손익 | G19: 2025.2Q | H19: =H15-SUM(H16:H18) -> -48625
A20: KR1000 | B20: 코리안리 | D20: 손해보험 | E20: =E9&"-1" -> 8-1 | F20: 장기재보험 출재손익 | G20: 2025.2Q | H20: =보험손익!D56-보험손익!D72 -> 18097
A21: KR1000 | B21: 코리안리 | D21: 손해보험 | E21: =E10&"-1" -> 9-1 | F21: 출재 CSM상각 | G21: 2025.2Q | H21: =-보험손익!D76 -> -3653
A22: KR1000 | B22: 코리안리 | D22: 손해보험 | E22: =E11&"-1" -> 10-1 | F22: 출재 위험조정 변동 | G22: 2025.2Q | H22: =-보험손익!D75 -> -88
A23: KR1000 | B23: 코리안리 | D23: 손해보험 | E23: =E12&"-1" -> 11-1 | F23: 출재 예실차 | G23: 2025.2Q | H23: =보험손익!D57-보험손익!D73-보험손익!D74 -> -397
A24: KR1000 | B24: 코리안리 | D24: 손해보험 | E24: =E13&"-1" -> 12-1 | F24: 기타 장기재보험 출재손익 | G24: 2025.2Q | H24: =H20-SUM(H21:H23) -> 22235
A25: KR1000 | B25: 코리안리 | D25: 손해보험 | E25: =E13+1 -> 13 | F25: 자동차손익 | G25: 2025.2Q
A26: KR1000 | B26: 코리안리 | D26: 손해보험 | E26: =E25+1 -> 14 | F26: 일반손익 | G26: 2025.2Q | H26: =보험손익!P14-보험손익!P34-보험손익!P72+보험손익!P56 -> 145033
A27: KR1000 | B27: 코리안리 | D27: 손해보험 | E27: =E26+1 -> 15 | F27: 기타영업수익 | G27: 2025.2Q
A28: KR1000 | B28: 코리안리 | D28: 손해보험 | E28: =E27+1 -> 16 | F28: 기타사업비용 | G28: 2025.2Q | H28: =49939464271/1000000 -> 49939.464
A29: KR1000 | B29: 코리안리 | D29: 손해보험 | E29: =E28+1 -> 17 | F29: 투자손익 | G29: 2025.2Q
A30: KR1000 | B30: 코리안리 | D30: 손해보험 | E30: =E29+1 -> 18 | F30: 투자이익 | G30: 2025.2Q
A31: KR1000 | B31: 코리안리 | D31: 손해보험 | E31: =E30+1 -> 19 | F31: 보험금융손익 | G31: 2025.2Q
A32: KR1000 | B32: 코리안리 | D32: 손해보험 | E32: =E31+1 -> 20 | F32: 영업이익 | G32: 2025.2Q
A33: KR1000 | B33: 코리안리 | D33: 손해보험 | E33: =E32+1 -> 21 | F33: 영업외손익 | G33: 2025.2Q
A34: KR1000 | B34: 코리안리 | D34: 손해보험 | E34: =E33+1 -> 22 | F34: 세전이익 | G34: 2025.2Q
A35: KR1000 | B35: 코리안리 | D35: 손해보험 | E35: =E34+1 -> 23 | F35: 법인세 | G35: 2025.2Q
A36: KR1000 | B36: 코리안리 | D36: 손해보험 | E36: =E35+1 -> 24 | F36: 당기순이익 | G36: 2025.2Q

Sheet 보험손익
A2: 19. 보험서비스결과
A5: 발행보험의 보험수익 분석 공시
A6: 당반기 | B6: (단위 : 백만원)
C7: 보험계약의 세분
C8: 발행한 보험계약
C9: 보험계약 | S9: 보험계약 합계
C10: 보험료배분접근법을 적용한 보험계약 외의 보험계약 | K10: 보험료배분접근법을 적용한 보험계약
C11: 계약의 유형 | I11: 계약의 유형 합계 | K11: 계약의 유형 | Q11: 계약의 유형 합계
C12: 장기보험 | E12: 생명보험 | G12: 일반보험 | K12: 장기보험 | M12: 생명보험 | O12: 일반보험
C13: 3개월 | D13: 누적 | E13: 3개월 | F13: 누적 | G13: 3개월 | H13: 누적 | I13: 3개월 | J13: 누적 | K13: 3개월 | L13: 누적 | M13: 3개월 | N13: 누적 | O13: 3개월 | P13: 누적 | Q13: 3개월 | R13: 누적 | S13: 3개월 | T13: 누적
A14: 보험수익 | C14: 157478 | D14: 309688 | E14: 176030 | F14: 353615 | G14: 0 | H14: 0 | I14: 333508 | J14: 663303 | K14: 0 | L14: 0 | M14: 0 | N14: 0 | O14: 889966 | P14: 1719380 | Q14: 889966 | R14: 1719380 | S14: 1223474 | T14: 2382683
A15: 보험수익 | B15: 보험수익, 예상 보험금 (기초 예상 측정치) | C15: 138421 | D15: 283211 | E15: 140715 | F15: 301343 | G15: 0 | H15: 0 | I15: 279136 | J15: 584554
B16: 보험수익, 예상 손해조사비 (기초 예상 측정치) | C16: 12557 | D16: 26225 | E16: 292 | F16: 578 | G16: 0 | H16: 0 | I16: 12849 | J16: 26803
B17: 보험수익, 예상 유지비 (기초 예상 측정치) | C17: 1469 | D17: 2972 | E17: 2991 | F17: 5997 | G17: 0 | H17: 0 | I17: 4460 | J17: 8969
B18: 보험수익, 예상 투자관리비 (기초 예상 측정치) | C18: 13 | D18: 17 | E18: 412 | F18: 823 | G18: 0 | H18: 0 | I18: 425 | J18: 840
B19: 보험수익, 비금융위험에 대한 위험조정의 변동분 | C19: 3081 | D19: 6289 | E19: 3905 | F19: 8435 | G19: 0 | H19: 0 | I19: 6986 | J19: 14724
B20: 보험수익, 서비스의 이전으로 당기손익에 인식한 보험계약마진 | C20: 8353 | D20: 16529 | E20: 10118 | F20: 20330 | G20: 0 | H20: 0 | I20: 18471 | J20: 36859
B21: 보험수익, 보험취득 현금흐름의 회수와 관련되는 보험료 부분의 배분액 | C21: 33 | D21: 59 | E21: 69 | F21: 151 | G21: 0 | H21: 0 | I21: 102 | J21: 210
B22: 보험수익, 손실요소 배분액 | C22: -543 | D22: -1329 | E22: -1657 | F22: -3123 | G22: 0 | H22: 0 | I22: -2200 | J22: -4452
B23: 보험수익, 그 밖의 금액 | C23: -5906 | D23: -24285 | E23: 19185 | F23: 19081 | G23: 0 | H23: 0 | I23: 13279 | J23: -5204
A25: 발행보험의 보험서비스비용 분석 공시 | D25: =D14-D34-D72+D56 -> 2721 | F25: =F14-F34-F72+F56 -> 61871 | J25: =J14-J34-J72+J56 -> 64592
A26: 당반기 | B26: (단위 : 백만원)
C27: 보험계약의 세분
C28: 발행한 보험계약
C29: 보험계약 | S29: 보험계약 합계
C30: 보험료배분접근법을 적용한 보험계약 외의 보험계약 | K30: 보험료배분접근법을 적용한 보험계약
C31: 계약의 유형 | I31: 계약의 유형 합계 | K31: 계약의 유형 | Q31: 계약의 유형 합계
C32: 장기보험 | E32: 생명보험 | G32: 일반보험 | K32: 장기보험 | M32: 생명보험 | O32: 일반보험
C33: 3개월 | D33: 누적 | E33: 3개월 | F33: 누적 | G33: 3개월 | H33: 누적 | I33: 3개월 | J33: 누적 | K33: 3개월 | L33: 누적 | M33: 3개월 | N33: 누적 | O33: 3개월 | P33: 누적 | Q33: 3개월 | R33: 누적 | S33: 3개월 | T33: 누적
A34: 보험비용 | C34: 147486 | D34: 325064 | E34: 124967 | F34: 290927 | G34: 0 | H34: 0 | I34: 272453 | J34: 615991 | K34: 0 | L34: 0 | M34: 0 | N34: 0 | O34: 822274 | P34: 1415112 | Q34: 822274 | R34: 1415112 | S34: 1094727 | T34: 2031103
A35: 보험비용 | B35: 보험서비스비용, 발생한 보험금 | C35: 144060 | D35: 273840 | E35: 193858 | F35: 344569 | G35: 0 | H35: 0 | I35: 337918 | J35: 618409
B36: 보험서비스비용, 발생한 손해조사비 | C36: 12429 | D36: 25243 | E36: 450 | F36: 784 | G36: 0 | H36: 0 | I36: 12879 | J36: 26027
B37: 보험서비스비용, 발생한 유지비 | C37: 1323 | D37: 2911 | E37: 4160 | F37: 8370 | G37: 0 | H37: 0 | I37: 5483 | J37: 11281
B38: 보험서비스비용, 발생한 투자관리비 | C38: 15 | D38: 26 | E38: 498 | F38: 972 | G38: 0 | H38: 0 | I38: 513 | J38: 998
B39: 보험서비스비용, 미래 서비스와 관련된 변동분에 관련된 금액 | C39: 1129 | D39: -329 | E39: -47684 | F39: -25561 | G39: 0 | H39: 0 | I39: -46555 | J39: -25890
B40: 보험서비스비용, 과거 서비스와 관련된 금액 | C40: -10961 | D40: 24638 | E40: -24936 | F40: -63934 | G40: 0 | H40: 0 | I40: -35897 | J40: -39296
B41: 보험서비스비용, 보험취득 현금흐름의 상각에 따른 금액 | C41: 33 | D41: 59 | E41: 69 | F41: 151 | G41: 0 | H41: 0 | I41: 102 | J41: 210
B42: 보험서비스비용, 손실요소 배분액 | C42: -543 | D42: -1329 | E42: -1657 | F42: -3123 | G42: 0 | H42: 0 | I42: -2200 | J42: -4452
B43: 보험서비스비용, 그 밖의 발생한 보험서비스비용 | C43: 1 | D43: 5 | E43: 209 | F43: 28699 | G43: 0 | H43: 0 | I43: 210 | J43: 28704
A45: 20. 재보험서비스결과
...
