Workbook

Sheet Sheet1
A1: 원보험사코드 | B1: 원수사명 | C1: 티커 | D1: 생손보여부 | E1: 항목번호 | F1: 항목명 | G1: 공시분기 | H1: 값 | I1: 검증
A2: KR0009 | B2: 현대해상 | D2: 손해보험 | E2: 1 | F2: 보험손익 | G2: 2026.1Q | H2: =H3+H14+H15+H16-H17 -> 302065.36 | I2: =ABS(ROUND(H2,0)-302065)<2 -> TRUE
A3: KR0009 | B3: 현대해상 | D3: 손해보험 | E3: =E2+1 -> 2 | F3: 생명장기 손익 | G3: 2026.1Q | H3: =H4+H9 -> 273309.26
A4: KR0009 | B4: 현대해상 | D4: 손해보험 | E4: =E3+1 -> 3 | F4: 생명장기 원수손익 | G4: 2026.1Q | H4: =(보험손익!B35-SUM(보험손익!B49))/1000000 -> 279302.34
A5: KR0009 | B5: 현대해상 | D5: 손해보험 | E5: =E4+1 -> 4 | F5: 원수 CSM상각 | G5: 2026.1Q | H5: =보험손익!B14/1000000 -> 241253.07
A6: KR0009 | B6: 현대해상 | D6: 손해보험 | E6: =E5+1 -> 5 | F6: 원수 위험조정 변동 | G6: 2026.1Q | H6: =보험손익!B13/1000000 -> 37321.917
A7: KR0009 | B7: 현대해상 | D7: 손해보험 | E7: =E6+1 -> 6 | F7: 원수 예실차 | G7: 2026.1Q | H7: =(보험손익!B12-보험손익!B45)/1000000 -> -126864.57
A8: KR0009 | B8: 현대해상 | D8: 손해보험 | E8: =E7+1 -> 7 | F8: 기타 생명장기 원수손익 | G8: 2026.1Q | H8: =H4-SUM(H5:H7) -> 127591.93
A9: KR0009 | B9: 현대해상 | D9: 손해보험 | E9: =E8+1 -> 8 | F9: 생명장기 재보험손익 | G9: 2026.1Q | H9: =(보험손익!B64-보험손익!B97)/1000000 -> -5993.0814
A10: KR0009 | B10: 현대해상 | D10: 손해보험 | E10: =E9+1 -> 9 | F10: 재보험 CSM상각 | G10: 2026.1Q | H10: =-보험손익!B76/1000000 -> -3441.7675
A11: KR0009 | B11: 현대해상 | D11: 손해보험 | E11: =E10+1 -> 10 | F11: 재보험 위험조정 변동 | G11: 2026.1Q | H11: =-보험손익!B75/1000000 -> -122.92907
A12: KR0009 | B12: 현대해상 | D12: 손해보험 | E12: =E11+1 -> 11 | F12: 재보험 예실차 | G12: 2026.1Q | H12: =(보험손익!B61-보험손익!B74)/1000000 -> 2075.3322
A13: KR0009 | B13: 현대해상 | D13: 손해보험 | E13: =E12+1 -> 12 | F13: 기타 생명장기 재보험손익 | G13: 2026.1Q | H13: =H9-SUM(H10:H12) -> -4503.7171
A14: KR0009 | B14: 현대해상 | D14: 손해보험 | E14: =E13+1 -> 13 | F14: 자동차손익 | G14: 2026.1Q | H14: =(보험손익!C35-보험손익!C49+보험손익!C64-보험손익!C97)/1000000 -> -10891.093
A15: KR0009 | B15: 현대해상 | D15: 손해보험 | E15: =E14+1 -> 14 | F15: 일반손익 | G15: 2026.1Q | H15: =(보험손익!D35-보험손익!D49+보험손익!D64-보험손익!D97)/1000000 -> 53726.46
A16: KR0009 | B16: 현대해상 | D16: 손해보험 | E16: =E15+1 -> 15 | F16: 기타영업수익 | G16: 2026.1Q
A17: KR0009 | B17: 현대해상 | D17: 손해보험 | E17: =E16+1 -> 16 | F17: 기타사업비용 | G17: 2026.1Q | H17: 14079.264
A18: KR0009 | B18: 현대해상 | D18: 손해보험 | E18: =E17+1 -> 17 | F18: 투자손익 | G18: 2026.1Q
A19: KR0009 | B19: 현대해상 | D19: 손해보험 | E19: =E18+1 -> 18 | F19: 투자이익 | G19: 2026.1Q
A20: KR0009 | B20: 현대해상 | D20: 손해보험 | E20: =E19+1 -> 19 | F20: 보험금융손익 | G20: 2026.1Q
A21: KR0009 | B21: 현대해상 | D21: 손해보험 | E21: =E20+1 -> 20 | F21: 영업이익 | G21: 2026.1Q
A22: KR0009 | B22: 현대해상 | D22: 손해보험 | E22: =E21+1 -> 21 | F22: 영업외손익 | G22: 2026.1Q
A23: KR0009 | B23: 현대해상 | D23: 손해보험 | E23: =E22+1 -> 22 | F23: 세전이익 | G23: 2026.1Q
A24: KR0009 | B24: 현대해상 | D24: 손해보험 | E24: =E23+1 -> 23 | F24: 법인세 | G24: 2026.1Q
A25: KR0009 | B25: 현대해상 | D25: 손해보험 | E25: =E24+1 -> 24 | F25: 당기순이익 | G25: 2026.1Q

Sheet 보험손익
A1: 20. 보험서비스결과
A4: 발행보험의 보험수익 분석 공시
A5: 당분기 | B5: (단위 : 원)
B6: 보험계약의 세분
B7: 발행한 보험계약
B8: 보험계약
B9: 보험료배분접근법을 적용한 보험계약 외의 보험계약
B10: 계약의 유형 | E10: 계약의 유형 합계
B11: 장기보험 | C11: 자동차보험 | D11: 일반보험
A12: 보험수익, 보고기간에 발생한 보험서비스비용 (기초 예상 측정치) | B12: 1522559947662 | C12: 0 | D12: 0 | E12: 1522559947662
A13: 보험수익, 비금융위험에 대한 위험조정의 변동분 | B13: 37321916556 | C13: 0 | D13: 0 | E13: 37321916556
A14: 보험수익, 서비스의 이전으로 당기손익에 인식한 보험계약마진 | B14: 241253066548 | C14: 0 | D14: 0 | E14: 241253066548
A15: 보험수익, 보험취득 현금흐름의 회수와 관련되는 보험료 부분의 배분액 | B15: 234300162478 | C15: 0 | D15: 0 | E15: 234300162478
A18: 발행보험의 보험수익 분석 공시, 보험료배분접근법을 적용한 보험계약
A19: 당분기 | B19: (단위 : 원)
B20: 보험계약의 세분
B21: 발행한 보험계약
B22: 보험계약
B23: 보험료배분접근법을 적용한 보험계약
B24: 계약의 유형 | E24: 계약의 유형 합계
B25: 장기보험 | C25: 자동차보험 | D25: 일반보험
A26: 보험수익 | B26: 0 | C26: 935161957739 | D26: 541615259664 | E26: 1476777217403
A29: 발행보험의 보험수익 분석 공시, 합계
A30: 당분기 | B30: (단위 : 원)
B31: 보험계약의 세분
B32: 발행한 보험계약
B33: 계약의 유형 | E33: 계약의 유형 합계
B34: 장기보험 | C34: 자동차보험 | D34: 일반보험
A35: 보험수익 | B35: 2035435093244 | C35: 935161957739 | D35: 541615259664 | E35: 3512212310647
A37: 발행보험의 보험서비스비용 분석 공시
A38: 당분기 | B38: (단위 : 원)
B39: 보험계약의 세분
B40: 발행한 보험계약
B41: 보험계약
B42: 보험료배분접근법을 적용한 보험계약 외의 보험계약
B43: 계약의 유형 | E43: 계약의 유형 합계
B44: 장기보험 | C44: 자동차보험 | D44: 일반보험
A45: 발생한 보험금 및 그 밖의 발생한 보험서비스비용에 따른 증가분(감소분), 보험계약부채(자산) | B45: 1649424518123 | C45: 834012803261 | D45: 230456026336 | E45: 2713893347720
A46: 보험취득 현금흐름의 상각에 따른 증가분(감소분), 보험계약부채(자산) | B46: 240759426215 | C46: 101283500109 | D46: 56081890775 | E46: 398124817099
A47: 과거 서비스와 관련된 변동분에 따른 증가분(감소분), 보험계약부채(자산) | B47: -52637373487 | C47: 9536737573 | D47: -14058837068 | E47: -57159472982
...
