Workbook

Sheet Sheet1
A1: 원보험사코드 | B1: 원수사명 | C1: 티커 | D1: 생손보여부 | E1: 항목번호 | F1: 항목명 | G1: 공시분기 | H1: 값 | I1: 검증
A2: KR0011 | B2: DB손보 | D2: 손해보험 | E2: 1 | F2: 보험손익 | G2: 2024.4Q | H2: =H3+H14+H15+H16-H17 -> 1097299.6 | I2: =ABS(ROUND(H2,0)-1097299.131966 )<2 -> TRUE
A3: KR0011 | B3: DB손보 | D3: 손해보험 | E3: =E2+1 -> 2 | F3: 생명장기 손익 | G3: 2024.4Q | H3: =H4+H9 -> 876668
A4: KR0011 | B4: DB손보 | D4: 손해보험 | E4: =E3+1 -> 3 | F4: 생명장기 원수손익 | G4: 2024.4Q | H4: =보험손익!C20-보험손익!C46 -> 951806
A5: KR0011 | B5: DB손보 | D5: 손해보험 | E5: =E4+1 -> 4 | F5: 원수 CSM상각 | G5: 2024.4Q | H5: =보험손익!C14 -> 653946
A6: KR0011 | B6: DB손보 | D6: 손해보험 | E6: =E5+1 -> 5 | F6: 원수 위험조정 변동 | G6: 2024.4Q | H6: =보험손익!C13 -> 57614
A7: KR0011 | B7: DB손보 | D7: 손해보험 | E7: =E6+1 -> 6 | F7: 원수 예실차 | G7: 2024.4Q | H7: =보험손익!C8+보험손익!C10+보험손익!C11+보험손익!C12-보험손익!C27-보험손익!C30-보험손익!C31-보험손익!C32 -> 44183
A8: KR0011 | B8: DB손보 | D8: 손해보험 | E8: =E7+1 -> 7 | F8: 기타 생명장기 원수손익 | G8: 2024.4Q | H8: =H4-SUM(H5:H7) -> 196063
A9: KR0011 | B9: DB손보 | D9: 손해보험 | E9: =E8+1 -> 8 | F9: 생명장기 재보험손익 | G9: 2024.4Q | H9: =보험손익!C59-보험손익!C73 -> -75138
A10: KR0011 | B10: DB손보 | D10: 손해보험 | E10: =E9+1 -> 9 | F10: 재보험 CSM상각 | G10: 2024.4Q | H10: =-보험손익!C69 -> 9313
A11: KR0011 | B11: DB손보 | D11: 손해보험 | E11: =E10+1 -> 10 | F11: 재보험 위험조정 변동 | G11: 2024.4Q | H11: =-보험손익!C68 -> -1902
A12: KR0011 | B12: DB손보 | D12: 손해보험 | E12: =E11+1 -> 11 | F12: 재보험 예실차 | G12: 2024.4Q | H12: =-(보험손익!C65+보험손익!C66+보험손익!C67-보험손익!C52-보험손익!C53-보험손익!C54) -> -30208
A13: KR0011 | B13: DB손보 | D13: 손해보험 | E13: =E12+1 -> 12 | F13: 기타 생명장기 재보험손익 | G13: 2024.4Q | H13: =H9-SUM(H10:H12) -> -52341
A14: KR0011 | B14: DB손보 | D14: 손해보험 | E14: =E13+1 -> 13 | F14: 자동차손익 | G14: 2024.4Q | H14: =보험손익!G20-보험손익!G46+보험손익!G59-보험손익!G73 -> 172089
A15: KR0011 | B15: DB손보 | D15: 손해보험 | E15: =E14+1 -> 14 | F15: 일반손익 | G15: 2024.4Q | H15: =보험손익!E20-보험손익!E46+보험손익!E59-보험손익!E73 -> 100374
A16: KR0011 | B16: DB손보 | D16: 손해보험 | E16: =E15+1 -> 15 | F16: 기타영업수익 | G16: 2024.4Q
A17: KR0011 | B17: DB손보 | D17: 손해보험 | E17: =E16+1 -> 16 | F17: 기타사업비용 | G17: 2024.4Q | H17: =51831424221/1000000 -> 51831.424
A18: KR0011 | B18: DB손보 | D18: 손해보험 | E18: =E17+1 -> 17 | F18: 투자손익 | G18: 2024.4Q
A19: KR0011 | B19: DB손보 | D19: 손해보험 | E19: =E18+1 -> 18 | F19: 투자이익 | G19: 2024.4Q
A20: KR0011 | B20: DB손보 | D20: 손해보험 | E20: =E19+1 -> 19 | F20: 보험금융손익 | G20: 2024.4Q
A21: KR0011 | B21: DB손보 | D21: 손해보험 | E21: =E20+1 -> 20 | F21: 영업이익 | G21: 2024.4Q
A22: KR0011 | B22: DB손보 | D22: 손해보험 | E22: =E21+1 -> 21 | F22: 영업외손익 | G22: 2024.4Q
A23: KR0011 | B23: DB손보 | D23: 손해보험 | E23: =E22+1 -> 22 | F23: 세전이익 | G23: 2024.4Q
A24: KR0011 | B24: DB손보 | D24: 손해보험 | E24: =E23+1 -> 23 | F24: 법인세 | G24: 2024.4Q
A25: KR0011 | B25: DB손보 | D25: 손해보험 | E25: =E24+1 -> 24 | F25: 당기순이익 | G25: 2024.4Q

Sheet 보험손익
A1: 6. 보험수익 및 비용과 재보험수익 및 비용
A3: 6-1 당반기 및 전반기 중 발행한 보험계약의 보험수익은 다음과 같습니다.
A4: <당반기> | B4: (단위: 백만원)
A5: 구 분 | B5: 장 기 | D5: 일 반 | F5: 자동차 | H5: 합 계
B6: 3개월 | C6: 누적 | D6: 3개월 | E6: 누적 | F6: 3개월 | G6: 누적 | H6: 3개월 | I6: 누적
A7: <원수>
A8: 예상보험금 | B8: 1193588 | C8: 2382518 | D8: - | E8: - | F8: - | G8: - | H8: 1193588 | I8: 2382518
A9: 보험취득현금흐름상각 | B9: 383897 | C9: 755628 | D9: - | E9: - | F9: - | G9: - | H9: 383897 | I9: 755628
A10: 예상유지비 | B10: 105179 | C10: 208101 | D10: - | E10: - | F10: - | G10: - | H10: 105179 | I10: 208101
A11: 예상손해조사비 | B11: 48236 | C11: 96322 | D11: - | E11: - | F11: - | G11: - | H11: 48236 | I11: 96322
A12: 예상투자관리비 | B12: 7677 | C12: 15289 | D12: - | E12: - | F12: - | G12: - | H12: 7677 | I12: 15289
A13: 비금융위험에 대한 위험조정상각 | B13: 36519 | C13: 57614 | D13: - | E13: - | F13: - | G13: - | H13: 36519 | I13: 57614
A14: 보험계약마진상각 | B14: 331578 | C14: 653946 | D14: - | E14: - | F14: - | G14: - | H14: 331578 | I14: 653946
A15: 손실요소배분 | B15: -23220 | C15: -49827 | D15: - | E15: - | F15: - | G15: - | H15: -23220 | I15: -49827
A16: 보험료배분접근법적용계약 발생수익 | B16: - | C16: - | D16: 505320 | E16: 986800 | F16: 1056146 | G16: 2121882 | H16: 1561466 | I16: 3108682
A17: 소 계 | B17: 2083454 | C17: 4119591 | D17: 505320 | E17: 986800 | F17: 1056146 | G17: 2121882 | H17: 3644920 | I17: 7228273
A18: <수재>
A19: 보험료배분접근법적용계약 발생수익 | B19: - | C19: - | D19: 26113 | E19: 49442 | F19: - | G19: - | H19: 26113 | I19: 49442
A20: 합 계 | B20: 2083454 | C20: 4119591 | D20: 531433 | E20: 1036242 | F20: 1056146 | G20: 2121882 | H20: 3671033 | I20: 7277715
A22: 6-2 당반기 및 전반기의 발행한 보험계약의 보험비용은 다음과 같습니다.
A23: <당반기> | B23: (단위: 백만원)
A24: 구 분 | B24: 장 기 | D24: 일 반 | F24: 자동차 | H24: 합 계
B25: 3개월 | C25: 누적 | D25: 3개월 | E25: 누적 | F25: 3개월 | G25: 누적 | H25: 3개월 | I25: 누적
A26: <원수>
A27: 발생보험금 | B27: 1138442 | C27: 2327604 | D27: 297863 | E27: 666274 | F27: 798075 | G27: 1581791 | H27: 2234380 | I27: 4575669
A28: 보험취득현금흐름상각 | B28: 383897 | C28: 755628 | D28: 89220 | E28: 182198 | F28: - | G28: - | H28: 473117 | I28: 937826
A29: 보험취득현금흐름비용 | B29: - | C29: - | D29: 764 | E29: 1360 | F29: 111017 | G29: 213198 | H29: 111781 | I29: 214558
A30: 발생직접유지비 | B30: 115237 | C30: 215543 | D30: 10735 | E30: 29118 | F30: 41362 | G30: 80084 | H30: 167334 | I30: 324745
A31: 손해조사비 | B31: 53522 | C31: 107997 | D31: 41666 | E31: 72385 | F31: 71040 | G31: 141350 | H31: 166228 | I31: 321732
A32: 투자관리비 | B32: 3431 | C32: 6903 | D32: - | E32: - | F32: - | G32: - | H32: 3431 | I32: 6903
A33: 손실부담계약의 손실인식(환입) | B33: 35413 | C33: -66982 | D33: 126 | E33: 394 | F33: - | G33: -254 | H33: 35539 | I33: -66842
A34: 발생사고부채 조정 | B34: -39119 | C34: -110140 | D34: -112055 | E34: -286761 | F34: -41692 | G34: -70761 | H34: -192866 | I34: -467662
A35: 손실요소배분 | B35: -23220 | C35: -49827 | D35: - | E35: - | F35: - | G35: - | H35: -23220 | I35: -49827
A36: 신계약비 경험조정 | B36: -7150 | C36: -18941 | D36: - | E36: - | F36: - | G36: - | H36: -7150 | I36: -18941
A37: 소 계 | B37: 1660453 | C37: 3167785 | D37: 328319 | E37: 664968 | F37: 979802 | G37: 1945408 | H37: 2968574 | I37: 5778161
A38: <수재>
A39: 발생수재보험금 | B39: - | C39: - | D39: 50358 | E39: 143009 | F39: - | G39: - | H39: 50358 | I39: 143009
A40: 수재손해조사비 | B40: - | C40: - | D40: 104 | E40: 359 | F40: - | G40: - | H40: 104 | I40: 359
A41: 수재이익수수료 | B41: - | C41: - | D41: 539 | E41: 629 | F41: - | G41: - | H41: 539 | I41: 629
A42: 수재유지비 | B42: - | C42: - | D42: 53 | E42: 75 | F42: - | G42: - | H42: 53 | I42: 75
...
