Workbook

Sheet Sheet1
A1: 원보험사코드 | B1: 원수사명 | C1: 티커 | D1: 생손보여부 | E1: 항목번호 | F1: 항목명 | G1: 공시분기 | H1: 값 | I1: 검증
A2: KR0005 | B2: 흥국화재 | D2: 손해보험 | E2: 1 | F2: 보험손익 | G2: 2025.2Q | H2: =H3+H14+H15+H16-H17 -> 100361 | I2: =ABS(ROUND(H2,0)-100361)<2 -> TRUE
A3: KR0005 | B3: 흥국화재 | D3: 손해보험 | E3: =E2+1 -> 2 | F3: 생명장기 손익 | G3: 2025.2Q | H3: =H4+H9 -> 119396
A4: KR0005 | B4: 흥국화재 | D4: 손해보험 | E4: =E3+1 -> 3 | F4: 생명장기 원수손익 | G4: 2025.2Q | H4: =보험손익!G26+보험손익!O26-보험손익!F47-보험손익!N47 -> 110662
A5: KR0005 | B5: 흥국화재 | D5: 손해보험 | E5: =E4+1 -> 4 | F5: 원수 CSM상각 | G5: 2025.2Q | H5: =보험손익!G24+보험손익!O24 -> 115093
A6: KR0005 | B6: 흥국화재 | D6: 손해보험 | E6: =E5+1 -> 5 | F6: 원수 위험조정 변동 | G6: 2025.2Q | H6: =보험손익!G23+보험손익!O23 -> 19825
A7: KR0005 | B7: 흥국화재 | D7: 손해보험 | E7: =E6+1 -> 6 | F7: 원수 예실차 | G7: 2025.2Q | H7: =SUM(보험손익!G18:G19,보험손익!O18:O19)-SUM(보험손익!F39:F40,보험손익!N39:N40) -> -20243
A8: KR0005 | B8: 흥국화재 | D8: 손해보험 | E8: =E7+1 -> 7 | F8: 기타 생명장기 원수손익 | G8: 2025.2Q | H8: =H4-SUM(H5:H7) -> -4013
A9: KR0005 | B9: 흥국화재 | D9: 손해보험 | E9: =E8+1 -> 8 | F9: 생명장기 재보험손익 | G9: 2025.2Q | H9: =보험손익!F72+보험손익!N72-보험손익!F92-보험손익!N92 -> 8734
A10: KR0005 | B10: 흥국화재 | D10: 손해보험 | E10: =E9+1 -> 9 | F10: 재보험 CSM상각 | G10: 2025.2Q | H10: =-보험손익!F90 -> 11592
A11: KR0005 | B11: 흥국화재 | D11: 손해보험 | E11: =E10+1 -> 10 | F11: 재보험 위험조정 변동 | G11: 2025.2Q | H11: =-보험손익!F89 -> -1001
A12: KR0005 | B12: 흥국화재 | D12: 손해보험 | E12: =E11+1 -> 11 | F12: 재보험 예실차 | G12: 2025.2Q | H12: =SUM(보험손익!F65:F66,보험손익!N65:N66)-SUM(보험손익!F86:F86,보험손익!N86:N86) -> -1246
A13: KR0005 | B13: 흥국화재 | D13: 손해보험 | E13: =E12+1 -> 12 | F13: 기타 생명장기 재보험손익 | G13: 2025.2Q | H13: =H9-SUM(H10:H12) -> -611
A14: KR0005 | B14: 흥국화재 | D14: 손해보험 | E14: =E13+1 -> 13 | F14: 자동차손익 | G14: 2025.2Q | H14: =보험손익!K26+보험손익!S26-보험손익!J47-보험손익!R47+보험손익!J72+보험손익!R72-보험손익!J92-보험손익!R92 -> -9541
A15: KR0005 | B15: 흥국화재 | D15: 손해보험 | E15: =E14+1 -> 14 | F15: 일반손익 | G15: 2025.2Q | H15: =보험손익!I26+보험손익!Q26-보험손익!H47-보험손익!P47+보험손익!H72+보험손익!P72-보험손익!H92-보험손익!P92 -> 5184
A16: KR0005 | B16: 흥국화재 | D16: 손해보험 | E16: =E15+1 -> 15 | F16: 기타영업수익 | G16: 2025.2Q
A17: KR0005 | B17: 흥국화재 | D17: 손해보험 | E17: =E16+1 -> 16 | F17: 기타사업비용 | G17: 2025.2Q | H17: 14678
A18: KR0005 | B18: 흥국화재 | D18: 손해보험 | E18: =E17+1 -> 17 | F18: 투자손익 | G18: 2025.2Q
A19: KR0005 | B19: 흥국화재 | D19: 손해보험 | E19: =E18+1 -> 18 | F19: 투자이익 | G19: 2025.2Q
A20: KR0005 | B20: 흥국화재 | D20: 손해보험 | E20: =E19+1 -> 19 | F20: 보험금융손익 | G20: 2025.2Q
A21: KR0005 | B21: 흥국화재 | D21: 손해보험 | E21: =E20+1 -> 20 | F21: 영업이익 | G21: 2025.2Q
A22: KR0005 | B22: 흥국화재 | D22: 손해보험 | E22: =E21+1 -> 21 | F22: 영업외손익 | G22: 2025.2Q
A23: KR0005 | B23: 흥국화재 | D23: 손해보험 | E23: =E22+1 -> 22 | F23: 세전이익 | G23: 2025.2Q
A24: KR0005 | B24: 흥국화재 | D24: 손해보험 | E24: =E23+1 -> 23 | F24: 법인세 | G24: 2025.2Q
A25: KR0005 | B25: 흥국화재 | D25: 손해보험 | E25: =E24+1 -> 24 | F25: 당기순이익 | G25: 2025.2Q

Sheet 보험손익
A2: 28. 보험수익/ 29. 보험서비스비용
A4: 발행보험의 보험수익 분석 공시
A5: 발행보험의 보험수익 분석 공시
A6: 당반기 | B6: (단위 : 백만원)
F7: 보험계약의 세분
F8: 발행한 보험계약
F9: 보험계약
F10: 보험료배분접근법을 적용한 보험계약 외의 보험계약 | N10: 보험료배분접근법을 적용한 보험계약
F11: 계약의 유형 | L11: 계약의 유형 합계 | N11: 계약의 유형 | T11: 계약의 유형 합계
F12: 장기보험 | H12: 일반보험 | J12: 자동차보험 | N12: 장기보험 | P12: 일반보험 | R12: 자동차보험
F13: 3개월 | G13: 누적 | H13: 3개월 | I13: 누적 | J13: 3개월 | K13: 누적 | L13: 3개월 | M13: 누적 | N13: 3개월 | O13: 누적 | P13: 3개월 | Q13: 누적 | R13: 3개월 | S13: 누적 | T13: 3개월 | U13: 누적
A14: 보험수익
A15: 보험수익 | B15: 보험수익, 잔여보장부채의 변동과 관련되는 금액
B16: 보험수익, 잔여보장부채의 변동과 관련되는 금액 | C16: 총 보험수익, 잔여보장부채의 변동분과 관련되는 금액 | F16: 527341 | G16: 1062763 | H16: 0 | I16: 0 | J16: 0 | K16: 0 | L16: 527341 | M16: 1062763 | N16: 0 | O16: 0 | P16: 0 | Q16: 0 | R16: 0 | S16: 0 | T16: 0 | U16: 0
C17: 보험수익, 보고기간에 발생한 보험서비스비용 (기초 예상 측정치) | F17: 458661 | G17: 927845 | H17: 0 | I17: 0 | J17: 0 | K17: 0 | L17: 458661 | M17: 927845 | N17: 0 | O17: 0 | P17: 0 | Q17: 0 | R17: 0 | S17: 0 | T17: 0 | U17: 0
C18: 보험수익, 보고기간에 발생한 보험서비스비용 (기초 예상 측정치) | D18: 보험수익, 예상 보험금 (기초 예상 측정치) | F18: 406835 | G18: 822752 | H18: 0 | I18: 0 | J18: 0 | K18: 0 | L18: 406835 | M18: 822752 | N18: 0 | O18: 0 | P18: 0 | Q18: 0 | R18: 0 | S18: 0 | T18: 0 | U18: 0
D19: 보험수익, 예상 기타 보험서비스비용 (기초 예상 측정치) | F19: 51826 | G19: 105093 | H19: 0 | I19: 0 | J19: 0 | K19: 0 | L19: 51826 | M19: 105093 | N19: 0 | O19: 0 | P19: 0 | Q19: 0 | R19: 0 | S19: 0 | T19: 0 | U19: 0
D20: 보험수익, 예상 기타 보험서비스비용 (기초 예상 측정치) | E20: 보험수익, 예상 유지비 (기초 예상 측정치) | F20: 34181 | G20: 69484 | H20: 0 | I20: 0 | J20: 0 | K20: 0 | L20: 34181 | M20: 69484 | N20: 0 | O20: 0 | P20: 0 | Q20: 0 | R20: 0 | S20: 0 | T20: 0 | U20: 0
E21: 보험수익, 예상 투자관리비 (기초 예상 측정치) | F21: 2120 | G21: 4247 | H21: 0 | I21: 0 | J21: 0 | K21: 0 | L21: 2120 | M21: 4247 | N21: 0 | O21: 0 | P21: 0 | Q21: 0 | R21: 0 | S21: 0 | T21: 0 | U21: 0
E22: 보험수익, 예상 손해조사비 (기초 예상 측정치) | F22: 15525 | G22: 31362 | H22: 0 | I22: 0 | J22: 0 | K22: 0 | L22: 15525 | M22: 31362 | N22: 0 | O22: 0 | P22: 0 | Q22: 0 | R22: 0 | S22: 0 | T22: 0 | U22: 0
C23: 보험수익, 비금융위험에 대한 위험조정의 변동분 | F23: 9999 | G23: 19825 | H23: 0 | I23: 0 | J23: 0 | K23: 0 | L23: 9999 | M23: 19825 | N23: 0 | O23: 0 | P23: 0 | Q23: 0 | R23: 0 | S23: 0 | T23: 0 | U23: 0
C24: 보험수익, 서비스의 이전으로 당기손익에 인식한 보험계약마진 | F24: 58681 | G24: 115093 | H24: 0 | I24: 0 | J24: 0 | K24: 0 | L24: 58681 | M24: 115093 | N24: 0 | O24: 0 | P24: 0 | Q24: 0 | R24: 0 | S24: 0 | T24: 0 | U24: 0
B25: 보험수익, 보험취득 현금흐름의 회수와 관련되는 보험료 부분의 배분액 | F25: 59816 | G25: 118480 | H25: 0 | I25: 0 | J25: 0 | K25: 0 | L25: 59816 | M25: 118480 | N25: 0 | O25: 0 | P25: 0 | Q25: 0 | R25: 0 | S25: 0 | T25: 0 | U25: 0
B26: 보험수익 | F26: 587157 | G26: 1181243 | H26: 0 | I26: 0 | J26: 0 | K26: 0 | L26: 587157 | M26: 1181243 | N26: 0 | O26: 0 | P26: 36866 | Q26: 69976 | R26: 28069 | S26: 54980 | T26: 64935 | U26: 124956 | V26: =L26+T26 -> 652092 | W26: =M26+U26 -> 1306199
A28: 발행보험의 보험서비스비용 분석 공시
A29: 당반기 | B29: (단위 : 백만원)
E30: 보험계약의 세분
E31: 발행한 보험계약
E32: 보험계약
E33: 보험료배분접근법을 적용한 보험계약 외의 보험계약 | M33: 보험료배분접근법을 적용한 보험계약
E34: 계약의 유형 | K34: 계약의 유형 합계 | M34: 계약의 유형 | S34: 계약의 유형 합계
E35: 장기보험 | G35: 일반보험 | I35: 자동차보험 | M35: 장기보험 | O35: 일반보험 | Q35: 자동차보험
E36: 3개월 | F36: 누적 | G36: 3개월 | H36: 누적 | I36: 3개월 | J36: 누적 | K36: 3개월 | L36: 누적 | M36: 3개월 | N36: 누적 | O36: 3개월 | P36: 누적 | Q36: 3개월 | R36: 누적 | S36: 3개월 | T36: 누적
A37: 발행한 보험계약에서 생기는 보험서비스비용
A38: 발행한 보험계약에서 생기는 보험서비스비용 | B38: 보험서비스비용, 발생한 보험금 및 그 밖의 발생한 보험서비스비용 | E38: 485195 | F38: 948088 | G38: 0 | H38: 0 | I38: 0 | J38: 0 | K38: 485195 | L38: 948088 | M38: 0 | N38: 0 | O38: 10735 | P38: 21079 | Q38: 29187 | R38: 58177 | S38: 39922 | T38: 79256
B39: 보험서비스비용, 발생한 보험금 및 그 밖의 발생한 보험서비스비용 | C39: 보험서비스비용, 발생한 보험금 | E39: 430970 | F39: 838215 | G39: 0 | H39: 0 | I39: 0 | J39: 0 | K39: 430970 | L39: 838215 | M39: 0 | N39: 0 | O39: 7997 | P39: 15649 | Q39: 23800 | R39: 47459 | S39: 31797 | T39: 63108
C40: 보험서비스비용, 그 밖의 발생한 보험서비스비용 | E40: 54225 | F40: 109873 | G40: 0 | H40: 0 | I40: 0 | J40: 0 | K40: 54225 | L40: 109873 | M40: 0 | N40: 0 | O40: 2738 | P40: 5430 | Q40: 5387 | R40: 10718 | S40: 8125 | T40: 16148
C41: 보험서비스비용, 그 밖의 발생한 보험서비스비용 | D41: 보험서비스비용, 발생한 손해조사비 | E41: 17371 | F41: 34387 | G41: 0 | H41: 0 | I41: 0 | J41: 0 | K41: 17371 | L41: 34387 | M41: 0 | N41: 0 | O41: 678 | P41: 1219 | Q41: 2713 | R41: 5459 | S41: 3391 | T41: 6678
D42: 보험서비스비용, 발생한 투자관리비 | E42: 2507 | F42: 4798 | G42: 0 | H42: 0 | I42: 0 | J42: 0 | K42: 2507 | L42: 4798 | M42: 0 | N42: 0 | O42: 30 | P42: 54 | Q42: 18 | R42: 32 | S42: 48 | T42: 86
D43: 보험서비스비용, 발생한 유지비 | E43: 34347 | F43: 70688 | G43: 0 | H43: 0 | I43: 0 | J43: 0 | K43: 34347 | L43: 70688 | M43: 0 | N43: 0 | O43: 2030 | P43: 4157 | Q43: 2656 | R43: 5227 | S43: 4686 | T43: 9384
...
