Workbook

Sheet Sheet2
A1: 원보험사코드 | B1: 원수사명 | C1: 티커 | D1: 생손보여부 | E1: 항목번호 | F1: 항목명 | G1: 공시분기 | H1: 값 | I1: 검증
A2: KR0068 | B2: 한화생명 | D2: 생명보험 | E2: 1 | F2: 보험손익 | G2: 2025.2Q | H2: =H3+H14+H15+H16-H17 -> 175999 | I2: =ROUND(H2,0)=ROUND(포괄손익계산서!C8,0) -> TRUE
A3: KR0068 | B3: 한화생명 | D3: 생명보험 | E3: =E2+1 -> 2 | F3: 생명장기 손익 | G3: 2025.2Q | H3: =H4+H9 -> 235859
A4: KR0068 | B4: 한화생명 | D4: 생명보험 | E4: =E3+1 -> 3 | F4: 생명장기 원수손익 | G4: 2025.2Q | H4: =부문별!N20+부문별!Z20-부문별!M52-부문별!Y52 -> 242874
A5: KR0068 | B5: 한화생명 | D5: 생명보험 | E5: =E4+1 -> 4 | F5: 원수 CSM상각 | G5: 2025.2Q | H5: =부문별!N16+부문별!Z16 -> 394479
A6: KR0068 | B6: 한화생명 | D6: 생명보험 | E6: =E5+1 -> 5 | F6: 원수 위험조정 변동 | G6: 2025.2Q | H6: =부문별!N15+부문별!Z15-부문별!I131-부문별!Q131 -> 75507
A7: KR0068 | B7: 한화생명 | D7: 생명보험 | E7: =E6+1 -> 6 | F7: 원수 예실차 | G7: 2025.2Q | H7: =부문별!N14+부문별!Z14-부문별!M48-부문별!Y48 -> -123351
A8: KR0068 | B8: 한화생명 | D8: 생명보험 | E8: =E7+1 -> 7 | F8: 기타 생명장기 원수손익 | G8: 2025.2Q | H8: =H4-SUM(H5:H7) -> -103761
A9: KR0068 | B9: 한화생명 | D9: 생명보험 | E9: =E8+1 -> 8 | F9: 생명장기 재보험손익 | G9: 2025.2Q | H9: =+부문별!I106+부문별!Q106-부문별!I134-부문별!Q134 -> -7015
A10: KR0068 | B10: 한화생명 | D10: 생명보험 | E10: =E9+1 -> 9 | F10: 재보험 CSM상각 | G10: 2025.2Q | H10: =-부문별!I132-부문별!Q132 -> -14304
A11: KR0068 | B11: 한화생명 | D11: 생명보험 | E11: =E10+1 -> 10 | F11: 재보험 위험조정 변동 | G11: 2025.2Q | H11: =-부문별!I145-부문별!Q145 -> -450
A12: KR0068 | B12: 한화생명 | D12: 생명보험 | E12: =E11+1 -> 11 | F12: 재보험 예실차 | G12: 2025.2Q | H12: =+부문별!I103+부문별!Q103-부문별!I130-부문별!Q130 -> 15031
A13: KR0068 | B13: 한화생명 | D13: 생명보험 | E13: =E12+1 -> 12 | F13: 기타 생명장기 재보험손익 | G13: 2025.2Q | H13: =H9-SUM(H10:H12) -> -7292
A14: KR0068 | B14: 한화생명 | D14: 생명보험 | E14: =E13+1 -> 13 | F14: 자동차손익 | G14: 2025.2Q | H14: 0
A15: KR0068 | B15: 한화생명 | D15: 생명보험 | E15: =E14+1 -> 14 | F15: 일반손익 | G15: 2025.2Q | H15: 0
A16: KR0068 | B16: 한화생명 | D16: 생명보험 | E16: =E15+1 -> 15 | F16: 기타영업수익 | G16: 2025.2Q | H16: 0
A17: KR0068 | B17: 한화생명 | D17: 생명보험 | E17: =E16+1 -> 16 | F17: 기타사업비용 | G17: 2025.2Q | H17: =포괄손익계산서!C15 -> 59860
A18: KR0068 | B18: 한화생명 | D18: 생명보험 | E18: =E17+1 -> 17 | F18: 투자손익 | G18: 2025.2Q | H18: =포괄손익계산서!C16 -> 14893
A19: KR0068 | B19: 한화생명 | D19: 생명보험 | E19: =E18+1 -> 18 | F19: 투자이익 | G19: 2025.2Q | H19: =H18-H20 -> 2311824
A20: KR0068 | B20: 한화생명 | D20: 생명보험 | E20: =E19+1 -> 19 | F20: 보험금융손익 | G20: 2025.2Q | H20: =-포괄손익계산서!C28 -> -2296931 | I20: <- 투자손익에 '보험금융수익' 계정이 없음. 보험금융비용 차감만 처리함
A21: KR0068 | B21: 한화생명 | D21: 생명보험 | E21: =E20+1 -> 20 | F21: 영업이익 | G21: 2025.2Q | H21: =H2+H18 -> 190892 | I21: =ROUND(H21,0)=ROUND(포괄손익계산서!C38,0) -> TRUE
A22: KR0068 | B22: 한화생명 | D22: 생명보험 | E22: =E21+1 -> 21 | F22: 영업외손익 | G22: 2025.2Q | H22: =포괄손익계산서!C39 -> 32549
A23: KR0068 | B23: 한화생명 | D23: 생명보험 | E23: =E22+1 -> 22 | F23: 세전이익 | G23: 2025.2Q | H23: =H21+H22 -> 223441 | I23: =ROUND(H23,0)=ROUND(포괄손익계산서!C42,0) -> TRUE
A24: KR0068 | B24: 한화생명 | D24: 생명보험 | E24: =E23+1 -> 23 | F24: 법인세 | G24: 2025.2Q | H24: =포괄손익계산서!C43 -> 43740
A25: KR0068 | B25: 한화생명 | D25: 생명보험 | E25: =E24+1 -> 24 | F25: 당기순이익 | G25: 2025.2Q | H25: =H23-H24 -> 179701 | I25: =ROUND(H25,0)=ROUND(포괄손익계산서!C44,0) -> TRUE

Sheet 부문별
A1: 23. 보험서비스결과
A4: 발행보험의 보험수익 분석 공시
A5: 당반기 | B5: (단위 : 백만원)
C6: 보험계약의 세분
C7: 발행한 보험계약
C8: 보험계약
C9: 보험료배분접근법을 적용한 보험계약 외의 보험계약 | O9: 보험료배분접근법을 적용한 보험계약
C10: 계약의 유형 | M10: 계약의 유형 합계 | O10: 계약의 유형 | Y10: 계약의 유형 합계
C11: 사망보험 | E11: 건강보험 | G11: 연금저축보험 | I11: 변액보험 | K11: 기타보험 | O11: 사망보험 | Q11: 건강보험 | S11: 연금저축보험 | U11: 변액보험 | W11: 기타보험
C12: 3개월 | D12: 누적 | E12: 3개월 | F12: 누적 | G12: 3개월 | H12: 누적 | I12: 3개월 | J12: 누적 | K12: 3개월 | L12: 누적 | M12: 3개월 | N12: 누적 | O12: 3개월 | P12: 누적 | Q12: 3개월 | R12: 누적 | S12: 3개월 | T12: 누적 | U12: 3개월 | V12: 누적 | W12: 3개월 | X12: 누적 | Y12: 3개월 | Z12: 누적
A13: 보험수익
A14: 보험수익 | B14: 보험수익, 보고기간에 발생한 보험서비스비용 (기초 예상 측정치) | C14: 290189 | D14: 577752 | E14: 316446 | F14: 623221 | G14: 94892 | H14: 181281 | I14: 104653 | J14: 209803 | K14: 0 | L14: 0 | M14: 806180 | N14: 1592057
B15: 보험수익, 비금융위험에 대한 위험조정의 변동분 | C15: 14747 | D15: 30530 | E15: 15543 | F15: 32573 | G15: 3345 | H15: 6409 | I15: 3553 | J15: 6554 | K15: 0 | L15: 0 | M15: 37188 | N15: 76066
B16: 보험수익, 서비스의 이전으로 당기손익에 인식한 보험계약마진 | C16: 63181 | D16: 131641 | E16: 103194 | F16: 203607 | G16: 29168 | H16: 58584 | I16: 298 | J16: 647 | K16: 0 | L16: 0 | M16: 195841 | N16: 394479
B17: 보험수익, 손실요소 변동과 관련된 금액 | C17: -2317 | D17: -3367 | E17: -6984 | F17: -10359 | G17: -5114 | H17: -10000 | I17: -1072 | J17: -1233 | K17: 0 | L17: 0 | M17: -15487 | N17: -24959
B18: 보험수익, 보험취득 현금흐름의 회수와 관련되는 보험료 부분의 배분액 | C18: 136859 | D18: 272640 | E18: 86037 | F18: 163165 | G18: 20501 | H18: 40171 | I18: 1629 | J18: 3386 | K18: 0 | L18: 0 | M18: 245026 | N18: 479362
B19: 보험수익, 그 밖의 금액 | C19: 4784 | D19: 3064 | E19: 3903 | F19: 4821 | G19: 687 | H19: 4121 | I19: 0 | J19: 0 | K19: 0 | L19: 0 | M19: 9374 | N19: 12006
B20: 보험수익 | C20: 507443 | D20: 1012260 | E20: 518139 | F20: 1017028 | G20: 143479 | H20: 280566 | I20: 109061 | J20: 219157 | K20: 0 | L20: 0 | M20: 1278122 | N20: 2529011 | O20: 3362 | P20: 6650 | R20: 0 | T20: 0 | V20: 0 | X20: 0 | Y20: 3362 | Z20: 6650
A22: 전반기 | B22: (단위 : 백만원)
C23: 보험계약의 세분
C24: 발행한 보험계약
C25: 보험계약
C26: 보험료배분접근법을 적용한 보험계약 외의 보험계약 | O26: 보험료배분접근법을 적용한 보험계약
C27: 계약의 유형 | M27: 계약의 유형 합계 | O27: 계약의 유형 | Y27: 계약의 유형 합계
C28: 사망보험 | E28: 건강보험 | G28: 연금저축보험 | I28: 변액보험 | K28: 기타보험 | O28: 사망보험 | Q28: 건강보험 | S28: 연금저축보험 | U28: 변액보험 | W28: 기타보험
C29: 3개월 | D29: 누적 | E29: 3개월 | F29: 누적 | G29: 3개월 | H29: 누적 | I29: 3개월 | J29: 누적 | K29: 3개월 | L29: 누적 | M29: 3개월 | N29: 누적 | O29: 3개월 | P29: 누적 | Q29: 3개월 | R29: 누적 | S29: 3개월 | T29: 누적 | U29: 3개월 | V29: 누적 | W29: 3개월 | X29: 누적 | Y29: 3개월 | Z29: 누적
A30: 보험수익
A31: 보험수익 | B31: 보험수익, 보고기간에 발생한 보험서비스비용 (기초 예상 측정치) | C31: 285957 | D31: 570875 | E31: 284406 | F31: 562861 | G31: 76756 | H31: 144758 | I31: 111487 | J31: 223045 | K31: 0 | L31: 0 | M31: 758606 | N31: 1501539
B32: 보험수익, 비금융위험에 대한 위험조정의 변동분 | C32: 15939 | D32: 28222 | E32: 14355 | F32: 25382 | G32: 2470 | H32: 4267 | I32: 2986 | J32: 5880 | K32: 0 | L32: 0 | M32: 35750 | N32: 63751
B33: 보험수익, 서비스의 이전으로 당기손익에 인식한 보험계약마진 | C33: 82539 | D33: 168390 | E33: 98707 | F33: 197113 | G33: 24909 | H33: 48387 | I33: 9296 | J33: 21865 | K33: 0 | L33: 0 | M33: 215451 | N33: 435755
B34: 보험수익, 손실요소 변동과 관련된 금액 | C34: -242 | D34: -487 | E34: -3624 | F34: -8246 | G34: -3258 | H34: -6706 | I34: -15 | J34: -45 | K34: 0 | L34: 0 | M34: -7139 | N34: -15484
B35: 보험수익, 보험취득 현금흐름의 회수와 관련되는 보험료 부분의 배분액 | C35: 133893 | D35: 265384 | E35: 58941 | F35: 113221 | G35: 14723 | H35: 28510 | I35: 2045 | J35: 4194 | K35: 0 | L35: 0 | M35: 209602 | N35: 411309
B36: 보험수익, 그 밖의 금액 | C36: -6100 | D36: -177 | E36: -5795 | F36: -2373 | G36: -2484 | H36: -4226 | I36: 0 | J36: 6 | K36: 0 | L36: 0 | M36: -14379 | N36: -6770
B37: 보험수익 | C37: 511986 | D37: 1032207 | E37: 446990 | F37: 887958 | G37: 113116 | H37: 214990 | I37: 125799 | J37: 254945 | K37: 0 | L37: 0 | M37: 1197891 | N37: 2390100 | O37: 4371 | P37: 8715 | R37: 0 | T37: 0 | V37: 0 | X37: 0 | Y37: 4371 | Z37: 8715
A39: 발행보험의 보험서비스비용 분석 공시
A40: 당반기 | B40: (단위 : 백만원)
B41: 보험계약의 세분
B42: 발행한 보험계약
B43: 보험계약
B44: 보험료배분접근법을 적용한 보험계약 외의 보험계약 | N44: 보험료배분접근법을 적용한 보험계약
...

Sheet 포괄손익계산서
A1: 4-2. 포괄손익계산서
A2: 포괄손익계산서
A3: 제 77 기 반기 2025.01.01 부터 2025.06.30 까지
A4: 제 76 기 반기 2024.01.01 부터 2024.06.30 까지
A5: (단위 : 백만원)
B6: 제 77 기 반기 | D6: 제 76 기 반기
B7: 3개월 | C7: 누적 | D7: 3개월 | E7: 누적
A8: 보험손익 | B8: 71792 | C8: 175999 | D8: 183724 | E8: 274552
A9: 보험영업수익 | B9: 1285360 | C9: 2563295 | D9: 1260163 | E9: 2523822
A10: 보험수익 | B10: 1281484 | C10: 2535661 | D10: 1202262 | E10: 2398815
A11: 재보험수익 | B11: 3876 | C11: 27634 | D11: 57901 | E11: 125007
A12: 보험서비스비용 | B12: 1213568 | C12: 2387296 | D12: 1076439 | E12: 2249270
A13: 보험비용 | B13: 1175356 | C13: 2292787 | D13: 978024 | E13: 2041946
A14: 재보험비용 | B14: 6062 | C14: 34649 | D14: 66095 | E14: 128104
A15: 기타사업비용 | B15: 32150 | C15: 59860 | D15: 32320 | E15: 79220
A16: 투자손익 | B16: -5977 | C16: 14893 | D16: 28860 | E16: 99089
A17: 투자영업수익 | B17: 3005941 | C17: 5095039 | D17: 2236288 | E17: 4555140
A18: 재보험금융수익 | B18: 1377 | C18: 2632 | D18: 1372 | E18: 2466
A19: 이자수익 | B19: 660206 | C19: 1295174 | D19: 621482 | E19: 1248527
... A55: 총포괄손익 | B55: 146616 | C55: -610585 | D55: -889768 | E55: -1503771
A56: 주당이익(손실)
A57: 보통주기본주당이익 (단위 : 원) | B57: 57 | C57: 200 | D57: 222 | E57: 448
A58: 보통주희석주당이익 (단위 : 원) | B58: 57 | C58: 200 | D58: 222 | E58: 448
