Workbook

Sheet Sheet2
A1: 원보험사코드 | B1: 원수사명 | C1: 티커 | D1: 생손보여부 | E1: 항목번호 | F1: 항목명 | G1: 공시분기 | H1: 값 | I1: 검증
A2: KR0069 | B2: 삼성생명 | D2: 생명보험 | E2: 1 | F2: 보험손익 | G2: 2025.4Q | H2: =H3+H14+H15+H16-H17 -> 981030 | I2: =ROUND(H2,0)=ROUND(포괄손익계산서!B2,0) -> TRUE
A3: KR0069 | B3: 삼성생명 | D3: 생명보험 | E3: =E2+1 -> 2 | F3: 생명장기 손익 | G3: 2025.4Q | H3: =H4+H9 -> 1143194
A4: KR0069 | B4: 삼성생명 | D4: 생명보험 | E4: =E3+1 -> 3 | F4: 생명장기 원수손익 | G4: 2025.4Q | H4: =부문별!C7-부문별!C27 -> 1201842
A5: KR0069 | B5: 삼성생명 | D5: 생명보험 | E5: =E4+1 -> 4 | F5: 원수 CSM상각 | G5: 2025.4Q | H5: =부문별!C10 -> 1511636
A6: KR0069 | B6: 삼성생명 | D6: 생명보험 | E6: =E5+1 -> 5 | F6: 원수 위험조정 변동 | G6: 2025.4Q | H6: =부문별!C9 -> 347889
A7: KR0069 | B7: 삼성생명 | D7: 생명보험 | E7: =E6+1 -> 6 | F7: 원수 예실차 | G7: 2025.4Q | H7: =부문별!C8-부문별!C28 -> -136349
A8: KR0069 | B8: 삼성생명 | D8: 생명보험 | E8: =E7+1 -> 7 | F8: 기타 생명장기 원수손익 | G8: 2025.4Q | H8: =H4-SUM(H5:H7) -> -521334
A9: KR0069 | B9: 삼성생명 | D9: 생명보험 | E9: =E8+1 -> 8 | F9: 생명장기 재보험손익 | G9: 2025.4Q | H9: =-부문별!C48+부문별!C64 -> -58648
A10: KR0069 | B10: 삼성생명 | D10: 생명보험 | E10: =E9+1 -> 9 | F10: 재보험 CSM상각 | G10: 2025.4Q | H10: =+부문별!C67 -> -64118
A11: KR0069 | B11: 삼성생명 | D11: 생명보험 | E11: =E10+1 -> 10 | F11: 재보험 위험조정 변동 | G11: 2025.4Q | H11: =+부문별!C66 -> -9515
A12: KR0069 | B12: 삼성생명 | D12: 생명보험 | E12: =E11+1 -> 11 | F12: 재보험 예실차 | G12: 2025.4Q | H12: =-부문별!C49+부문별!C65 -> 7597
A13: KR0069 | B13: 삼성생명 | D13: 생명보험 | E13: =E12+1 -> 12 | F13: 기타 생명장기 재보험손익 | G13: 2025.4Q | H13: =H9-SUM(H10:H12) -> 7388
A14: KR0069 | B14: 삼성생명 | D14: 생명보험 | E14: =E13+1 -> 13 | F14: 자동차손익 | G14: 2025.4Q | H14: 0
A15: KR0069 | B15: 삼성생명 | D15: 생명보험 | E15: =E14+1 -> 14 | F15: 일반손익 | G15: 2025.4Q | H15: 0
A16: KR0069 | B16: 삼성생명 | D16: 생명보험 | E16: =E15+1 -> 15 | F16: 기타영업수익 | G16: 2025.4Q | H16: 0
A17: KR0069 | B17: 삼성생명 | D17: 생명보험 | E17: =E16+1 -> 16 | F17: 기타사업비용 | G17: 2025.4Q | H17: =포괄손익계산서!B9 -> 162164
A18: KR0069 | B18: 삼성생명 | D18: 생명보험 | E18: =E17+1 -> 17 | F18: 투자손익 | G18: 2025.4Q | H18: =포괄손익계산서!B10 -> 1599439
A19: KR0069 | B19: 삼성생명 | D19: 생명보험 | E19: =E18+1 -> 18 | F19: 투자이익 | G19: 2025.4Q | H19: =H18-H20 -> 12172459
A20: KR0069 | B20: 삼성생명 | D20: 생명보험 | E20: =E19+1 -> 19 | F20: 보험금융손익 | G20: 2025.4Q | H20: =포괄손익계산서!B12-포괄손익계산서!B26 -> -10573020
A21: KR0069 | B21: 삼성생명 | D21: 생명보험 | E21: =E20+1 -> 20 | F21: 영업이익 | G21: 2025.4Q | H21: =H2+H18 -> 2580469 | I21: =ROUND(H21,0)=ROUND(포괄손익계산서!B36,0) -> TRUE
A22: KR0069 | B22: 삼성생명 | D22: 생명보험 | E22: =E21+1 -> 21 | F22: 영업외손익 | G22: 2025.4Q | H22: =포괄손익계산서!B37 -> 415876
A23: KR0069 | B23: 삼성생명 | D23: 생명보험 | E23: =E22+1 -> 22 | F23: 세전이익 | G23: 2025.4Q | H23: =H21+H22 -> 2996345 | I23: =ROUND(H23,0)=ROUND(포괄손익계산서!B40,0) -> TRUE
A24: KR0069 | B24: 삼성생명 | D24: 생명보험 | E24: =E23+1 -> 23 | F24: 법인세 | G24: 2025.4Q | H24: =포괄손익계산서!B41 -> 544830
A25: KR0069 | B25: 삼성생명 | D25: 생명보험 | E25: =E24+1 -> 24 | F25: 당기순이익 | G25: 2025.4Q | H25: =H23-H24 -> 2451515 | I25: =ROUND(H25,0)=ROUND(포괄손익계산서!B43,0) -> TRUE

Sheet 부문별
A1: 23-1. 보험서비스수익 및 보험서비스비용 (연결)
A4: 발행보험의 보험수익 분석 공시
A5: 당기 | B5: (단위 : 백만원)
C6: 발행한 보험계약
A7: 일반보험서비스수익 | C7: 9718551
A8: 일반보험서비스수익 | B8: 예상 발생보험금 및 보험서비스비용 | C8: 6784590 | E8: =C8-C28-C49+C65 -> -128752
B9: 위험해제로 인한 비금융위험에 대한 위험조정의 변동 | C9: 347889 | E9: =C9+C66 -> 338374
B10: 제공된 서비스의 보험계약마진 | C10: 1511636 | E10: =C10+C67 -> 1447518
B11: 손실요소 변동 | C11: -25860
B12: 보험취득현금흐름의 회수 | C12: 1100296
A14: 전기 | B14: (단위 : 백만원)
C15: 발행한 보험계약
A16: 일반보험서비스수익 | C16: 9011262
A17: 일반보험서비스수익 | B17: 예상 발생보험금 및 보험서비스비용 | C17: 6520971
B18: 위험해제로 인한 비금융위험에 대한 위험조정의 변동 | C18: 323468
B19: 제공된 서비스의 보험계약마진 | C19: 1393380
B20: 손실요소 변동 | C20: -11444
B21: 보험취득현금흐름의 회수 | C21: 784887
A24: 발행보험의 보험서비스비용 분석 공시
A25: 당기 | B25: (단위 : 백만원)
C26: 발행한 보험계약
A27: 일반보험서비스비용 | C27: 8516709
A28: 일반보험서비스비용 | B28: 실제 발생보험금 및 보험서비스비용 | C28: 6920939
B29: 발생사고 이행현금흐름 변동 | C29: 131253
B30: 손실부담계약의 손실 및 손실 환입 | C30: 364221
B31: 보험취득현금흐름의 회수 | C31: 1100296
A33: 전기 | B33: (단위 : 백만원)
C34: 발행한 보험계약
A35: 일반보험서비스비용 | C35: 8358057
A36: 일반보험서비스비용 | B36: 실제 발생보험금 및 보험서비스비용 | C36: 6714214
B37: 발생사고 이행현금흐름 변동 | C37: 335978
B38: 손실부담계약의 손실 및 손실 환입 | C38: 522978
B39: 보험취득현금흐름의 회수 | C39: 784887
A42: 23-2. 재보험서비스수익 및 재보험서비스비용 (연결)
A45: 재보험서비스수익
A46: 당기 | B46: (단위 : 백만원)
C47: 보유 재보험계약
A48: 출재보험서비스수익 | C48: -171891
A49: 출재보험서비스수익 | B49: 실제 발생보험금 및 보험서비스비용 | C49: -179290
B50: 발생사고 이행현금흐름 변동 | C50: 7438
...

Sheet 포괄손익계산서
B1: 제 70 기 | C1: 제 69 기 | D1: 제 68 기
A2: 보험서비스결과 | B2: 981030 | C2: 536631 | D2: 1448232 | F2: 974742.62
A3: 보험서비스수익 | B3: 9890442 | C3: 9190107 | D3: 8672104
A4: 일반보험서비스수익 | B4: 9718551 | C4: 9011262 | D4: 8536474
A5: 출재보험서비스수익 | B5: 171891 | C5: 178845 | D5: 135630
A6: 보험서비스비용 | B6: 8909412 | C6: 8653476 | D6: 7223872
A7: 일반보험서비스비용 | B7: 8516709 | C7: 8358057 | D7: 7000247
A8: 출재보험서비스비용 | B8: 230539 | C8: 199896 | D8: 162865
A9: 기타사업비용 | B9: 162164 | C9: 95523 | D9: 60760
A10: 투자손익 | B10: 1599439 | C10: 1963120 | D10: 950145
A11: 투자서비스수익 | B11: 27247868 | C11: 24595922 | D11: 22264910
A12: 보험금융수익 | B12: 1672566 | C12: 1825902 | D12: 1404187
A13: 재보험금융수익 | B13: 111959 | C13: 92551 | D13: 47678
A14: 이자수익 | B14: 8406565 | C14: 8460953 | D14: 8437019
... A55: 총포괄손익 | B55: 27606924 | C55: -13246381 | D55: 6700803
A56: 당기순이익(손실)의 귀속
A57: 지배기업의 소유주에게 귀속되는 당기순이익(손실) | B57: 2302837 | C57: 2106839 | D57: 1895312
A58: 지배기업의 소유주에게 귀속될 계속영업손익 | B58: 2302837 | C58: 2106839 | D58: 1895312
A59: 비지배지분에 귀속되는 당기순이익(손실) | B59: 148678 | C59: 153416 | D59: 138397
A60: 비지배지분에 귀속될 계속영업이익(손실) | B60: 148678 | C60: 153416 | D60: 138397
A61: 포괄손익의 귀속
A62: 지배기업의 소유주에게 귀속되는 총포괄손익 | B62: 27434788 | C62: -13410642 | D62: 6580989
A63: 지배기업의 소유주에게 귀속되는 계속영업포괄손익 | B63: 27434788 | C63: -13410642 | D63: 6580989
A64: 비지배지분에 귀속되는 총포괄손익 | B64: 172136 | C64: 164261 | D64: 119814
A65: 비지배지분에 귀속되는 계속영업포괄손익 | B65: 172136 | C65: 164261 | D65: 119814
A66: 주당이익
A67: 기본주당이익(손실)(단위:원) (단위 : 원) | B67: 12824 | C67: 11732 | D67: 10554
A68: 보통주희석주당이익(손실) (단위 : 원) | B68: 12824 | C68: 11732 | D68: 10554
