Workbook

Sheet Sheet1
A1: 원보험사코드 | B1: 원수사명 | C1: 티커 | D1: 생손보여부 | E1: 항목번호 | F1: 항목명 | G1: 공시분기 | H1: 값 | I1: 검증
A2: KR0003 | B2: 롯데손보 | D2: 손해보험 | E2: 1 | F2: 보험손익 | G2: 2026.1Q | H2: =H3+H14+H15+H16-H17 -> 27200
A3: KR0003 | B3: 롯데손보 | D3: 손해보험 | E3: =E2+1 -> 2 | F3: 생명장기 손익 | G3: 2026.1Q | H3: =H4+H9 -> 37418
A4: KR0003 | B4: 롯데손보 | D4: 손해보험 | E4: =E3+1 -> 3 | F4: 생명장기 원수손익 | G4: 2026.1Q | H4: =보험손익!C18-보험손익!C52 -> 44524
A5: KR0003 | B5: 롯데손보 | D5: 손해보험 | E5: =E4+1 -> 4 | F5: 원수 CSM상각 | G5: 2026.1Q | H5: =보험손익!C16 -> 58694
A6: KR0003 | B6: 롯데손보 | D6: 손해보험 | E6: =E5+1 -> 5 | F6: 원수 위험조정 변동 | G6: 2026.1Q | H6: =보험손익!C15 -> 8270
A7: KR0003 | B7: 롯데손보 | D7: 손해보험 | E7: =E6+1 -> 6 | F7: 원수 예실차 | G7: 2026.1Q | H7: =보험손익!C14-보험손익!C48 -> -26864
A8: KR0003 | B8: 롯데손보 | D8: 손해보험 | E8: =E7+1 -> 7 | F8: 기타 생명장기 원수손익 | G8: 2026.1Q | H8: =H4-SUM(H5:H7) -> 4424
A9: KR0003 | B9: 롯데손보 | D9: 손해보험 | E9: =E8+1 -> 8 | F9: 생명장기 재보험손익 | G9: 2026.1Q | H9: =보험손익!C68-보험손익!C82-보험손익!B93 -> -7106
A10: KR0003 | B10: 롯데손보 | D10: 손해보험 | E10: =E9+1 -> 9 | F10: 재보험 CSM상각 | G10: 2026.1Q | H10: =-보험손익!C81 -> -3352
A11: KR0003 | B11: 롯데손보 | D11: 손해보험 | E11: =E10+1 -> 10 | F11: 재보험 위험조정 변동 | G11: 2026.1Q | H11: =-보험손익!C80 -> -601
A12: KR0003 | B12: 롯데손보 | D12: 손해보험 | E12: =E11+1 -> 11 | F12: 재보험 예실차 | G12: 2026.1Q | H12: =보험손익!D65-보험손익!C79 -> -3711
A13: KR0003 | B13: 롯데손보 | D13: 손해보험 | E13: =E12+1 -> 12 | F13: 기타 생명장기 재보험손익 | G13: 2026.1Q | H13: =H9-SUM(H10:H12) -> 558
A14: KR0003 | B14: 롯데손보 | D14: 손해보험 | E14: =E13+1 -> 13 | F14: 자동차손익 | G14: 2026.1Q | H14: =보험손익!E18+보험손익!D29-보험손익!E52-보험손익!E82-보험손익!D93+보험손익!E68 -> -5419
A15: KR0003 | B15: 롯데손보 | D15: 손해보험 | E15: =E14+1 -> 14 | F15: 일반손익 | G15: 2026.1Q | H15: =보험손익!D18+보험손익!C29-보험손익!D52-보험손익!D82-보험손익!C93+보험손익!D68 -> 1062
A16: KR0003 | B16: 롯데손보 | D16: 손해보험 | E16: =E15+1 -> 15 | F16: 기타영업수익 | G16: 2026.1Q
A17: KR0003 | B17: 롯데손보 | D17: 손해보험 | E17: =E16+1 -> 16 | F17: 기타사업비용 | G17: 2026.1Q | H17: 5861
A18: KR0003 | B18: 롯데손보 | D18: 손해보험 | E18: =E17+1 -> 17 | F18: 투자손익 | G18: 2026.1Q
A19: KR0003 | B19: 롯데손보 | D19: 손해보험 | E19: =E18+1 -> 18 | F19: 투자이익 | G19: 2026.1Q
A20: KR0003 | B20: 롯데손보 | D20: 손해보험 | E20: =E19+1 -> 19 | F20: 보험금융손익 | G20: 2026.1Q
A21: KR0003 | B21: 롯데손보 | D21: 손해보험 | E21: =E20+1 -> 20 | F21: 영업이익 | G21: 2026.1Q
A22: KR0003 | B22: 롯데손보 | D22: 손해보험 | E22: =E21+1 -> 21 | F22: 영업외손익 | G22: 2026.1Q
A23: KR0003 | B23: 롯데손보 | D23: 손해보험 | E23: =E22+1 -> 22 | F23: 세전이익 | G23: 2026.1Q
A24: KR0003 | B24: 롯데손보 | D24: 손해보험 | E24: =E23+1 -> 23 | F24: 법인세 | G24: 2026.1Q
A25: KR0003 | B25: 롯데손보 | D25: 손해보험 | E25: =E24+1 -> 24 | F25: 당기순이익 | G25: 2026.1Q

Sheet 보험손익
A2: 25. 보험손익
A5: 발행보험의 보험수익 분석 공시, 보험료배분접근법을 적용한 보험계약 외의 보험계약
A6: 당분기 | B6: (단위 : 백만원)
C7: 보험계약의 세분
C8: 발행한 보험계약
C9: 보험계약
C10: 보험료배분접근법을 적용한 보험계약 외의 보험계약
C11: 계약의 유형 | F11: 계약의 유형 합계
C12: 장기 | D12: 일반 | E12: 자동차
A13: 보험수익
A14: 보험수익 | B14: 예상보험금 및 예상기타보험서비스비용 | C14: 305371 | D14: 0 | E14: 0 | F14: 305371
B15: 위험조정 변동 | C15: 8270 | D15: 0 | E15: 0 | F15: 8270
B16: 보험계약마진 상각 | C16: 58694 | D16: 0 | E16: 0 | F16: 58694
B17: 보험취득현금흐름 상각 | C17: 110675 | D17: 0 | E17: 0 | F17: 110675
B18: 보험수익 | C18: 483010 | D18: 0 | E18: 0 | F18: 483010
A21: 발행보험의 보험수익 분석 공시, 보험료배분접근법을 적용한 보험계약
A22: 당분기 | B22: (단위 : 백만원)
B23: 보험계약의 세분
B24: 발행한 보험계약
B25: 보험계약
B26: 보험료배분접근법을 적용한 보험계약
B27: 계약의 유형 | E27: 계약의 유형 합계
B28: 장기 | C28: 일반 | D28: 자동차
A29: 보험수익 | B29: 0 | C29: 36082 | D29: 32481 | E29: 68563
A32: 발행보험의 보험수익 분석 공시, 합계
A33: 당분기 | B33: (단위 : 백만원)
B34: 보험계약의 세분
B35: 발행한 보험계약
B36: 계약의 유형 | E36: 계약의 유형 합계
B37: 장기 | C37: 일반 | D37: 자동차
A38: 총 보험수익 | B38: 483010 | C38: 36082 | D38: 32481 | E38: 551573
A41: 발행보험의 보험서비스비용 분석 공시
A42: 당분기 | B42: (단위 : 백만원)
C43: 보험계약의 세분
C44: 발행한 보험계약
C45: 계약의 유형 | F45: 계약의 유형 합계
C46: 장기 | D46: 일반 | E46: 자동차
A47: 보험비용
A48: 보험비용 | B48: 발생보험금 및 기타서비스비용 | C48: 332235 | D48: 25001 | E48: 35013 | F48: 392249
B49: 보험취득현금흐름 상각 | C49: 110675 | D49: 5398 | E49: 4366 | F49: 120439
...
