Workbook

Sheet Sheet2
A1: 원보험사코드 | B1: 원수사명 | C1: 티커 | D1: 생손보여부 | E1: 항목번호 | F1: 항목명 | G1: 공시분기 | H1: 값 | I1: 검증
A2: KR0068 | B2: 한화생명 | D2: 생명보험 | E2: 1 | F2: 보험손익 | G2: 2025.4Q | H2: =H3+H14+H15+H16-H17 -> 344419 | I2: =ROUND(H2,0)=ROUND(포괄손익계산서!B8,0) -> TRUE
A3: KR0068 | B3: 한화생명 | D3: 생명보험 | E3: =E2+1 -> 2 | F3: 생명장기 손익 | G3: 2025.4Q | H3: =H4+H9 -> 491336
A4: KR0068 | B4: 한화생명 | D4: 생명보험 | E4: =E3+1 -> 3 | F4: 생명장기 원수손익 | G4: 2025.4Q | H4: =부문별!H19+부문별!N19-부문별!G34-부문별!M34 -> 495776
A5: KR0068 | B5: 한화생명 | D5: 생명보험 | E5: =E4+1 -> 4 | F5: 원수 CSM상각 | G5: 2025.4Q | H5: =부문별!H15+부문별!N15 -> 787290
A6: KR0068 | B6: 한화생명 | D6: 생명보험 | E6: =E5+1 -> 5 | F6: 원수 위험조정 변동 | G6: 2025.4Q | H6: =부문별!H14+부문별!N14 -> 155559
A7: KR0068 | B7: 한화생명 | D7: 생명보험 | E7: =E6+1 -> 6 | F7: 원수 예실차 | G7: 2025.4Q | H7: =부문별!H13+부문별!N13-부문별!G30-부문별!M30 -> -406421
A8: KR0068 | B8: 한화생명 | D8: 생명보험 | E8: =E7+1 -> 7 | F8: 기타 생명장기 원수손익 | G8: 2025.4Q | H8: =H3-SUM(H5:H7) -> -45092
A9: KR0068 | B9: 한화생명 | D9: 생명보험 | E9: =E8+1 -> 8 | F9: 생명장기 재보험손익 | G9: 2025.4Q | H9: =+부문별!E63+부문별!I63-부문별!E78-부문별!I78 -> -4440
A10: KR0068 | B10: 한화생명 | D10: 생명보험 | E10: =E9+1 -> 9 | F10: 재보험 CSM상각 | G10: 2025.4Q | H10: =-부문별!E76-부문별!I76 -> -31505
A11: KR0068 | B11: 한화생명 | D11: 생명보험 | E11: =E10+1 -> 10 | F11: 재보험 위험조정 변동 | G11: 2025.4Q | H11: =-부문별!E75-부문별!I75 -> -1125
A12: KR0068 | B12: 한화생명 | D12: 생명보험 | E12: =E11+1 -> 11 | F12: 재보험 예실차 | G12: 2025.4Q | H12: =+부문별!E60+부문별!I60-부문별!E74-부문별!I74 -> 33157
A13: KR0068 | B13: 한화생명 | D13: 생명보험 | E13: =E12+1 -> 12 | F13: 기타 생명장기 재보험손익 | G13: 2025.4Q | H13: =H9-SUM(H10:H12) -> -4967
A14: KR0068 | B14: 한화생명 | D14: 생명보험 | E14: =E13+1 -> 13 | F14: 자동차손익 | G14: 2025.4Q | H14: 0
A15: KR0068 | B15: 한화생명 | D15: 생명보험 | E15: =E14+1 -> 14 | F15: 일반손익 | G15: 2025.4Q | H15: 0
A16: KR0068 | B16: 한화생명 | D16: 생명보험 | E16: =E15+1 -> 15 | F16: 기타영업수익 | G16: 2025.4Q | H16: 0
A17: KR0068 | B17: 한화생명 | D17: 생명보험 | E17: =E16+1 -> 16 | F17: 기타사업비용 | G17: 2025.4Q | H17: =포괄손익계산서!B15 -> 146917
A18: KR0068 | B18: 한화생명 | D18: 생명보험 | E18: =E17+1 -> 17 | F18: 투자손익 | G18: 2025.4Q | H18: =포괄손익계산서!B16 -> 57018
A19: KR0068 | B19: 한화생명 | D19: 생명보험 | E19: =E18+1 -> 18 | F19: 투자이익 | G19: 2025.4Q | H19: =H18-H20 -> 4416182
A20: KR0068 | B20: 한화생명 | D20: 생명보험 | E20: =E19+1 -> 19 | F20: 보험금융손익 | G20: 2025.4Q | H20: =-포괄손익계산서!B28 -> -4359164 | I20: <- 투자손익에 '보험금융수익' 계정이 없음. 보험금융비용 차감만 처리함
A21: KR0068 | B21: 한화생명 | D21: 생명보험 | E21: =E20+1 -> 20 | F21: 영업이익 | G21: 2025.4Q | H21: =H2+H18 -> 401437 | I21: =ROUND(H21,0)=ROUND(포괄손익계산서!B38,0) -> TRUE
A22: KR0068 | B22: 한화생명 | D22: 생명보험 | E22: =E21+1 -> 21 | F22: 영업외손익 | G22: 2025.4Q | H22: =포괄손익계산서!B39 -> 11213
A23: KR0068 | B23: 한화생명 | D23: 생명보험 | E23: =E22+1 -> 22 | F23: 세전이익 | G23: 2025.4Q | H23: =H21+H22 -> 412650 | I23: =ROUND(H23,0)=ROUND(포괄손익계산서!B42,0) -> TRUE
A24: KR0068 | B24: 한화생명 | D24: 생명보험 | E24: =E23+1 -> 23 | F24: 법인세 | G24: 2025.4Q | H24: =포괄손익계산서!B43 -> 99330
A25: KR0068 | B25: 한화생명 | D25: 생명보험 | E25: =E24+1 -> 24 | F25: 당기순이익 | G25: 2025.4Q | H25: =H23-H24 -> 313320 | I25: =ROUND(H25,0)=ROUND(포괄손익계산서!B44,0) -> TRUE

Sheet 부문별
A1: 22. 보험서비스결과
A4: 발행보험의 보험수익 분석 공시
A5: 당기 | B5: (단위 : 백만원)
C6: 보험계약의 세분
C7: 발행한 보험계약
C8: 보험계약
C9: 보험료배분접근법을 적용한 보험계약 외의 보험계약 | I9: 보험료배분접근법을 적용한 보험계약
C10: 계약의 유형 | H10: 계약의 유형 합계 | I10: 계약의 유형 | N10: 계약의 유형 합계
C11: 사망보험 | D11: 건강보험 | E11: 연금저축보험 | F11: 변액보험 | G11: 기타보험 | I11: 사망보험 | J11: 건강보험 | K11: 연금저축보험 | L11: 변액보험 | M11: 기타보험
A12: 보험수익
A13: 보험수익 | B13: 보험수익, 보고기간에 발생한 보험서비스비용 (기초 예상 측정치) | C13: 1169322 | D13: 1274263 | E13: 372499 | F13: 418159 | G13: 0 | H13: 3234243
B14: 보험수익, 비금융위험에 대한 위험조정의 변동분 | C14: 60834 | D14: 70867 | E14: 11621 | F14: 12237 | G14: 0 | H14: 155559
B15: 보험수익, 서비스의 이전으로 당기손익에 인식한 보험계약마진 | C15: 251198 | D15: 412271 | E15: 122651 | F15: 1170 | G15: 0 | H15: 787290
B16: 보험수익, 손실요소 변동과 관련된 금액 | C16: -7852 | D16: -14172 | E16: -19733 | F16: -4994 | G16: 0 | H16: -46751
B17: 보험수익, 보험취득 현금흐름의 회수와 관련되는 보험료 부분의 배분액 | C17: 560560 | D17: 358308 | E17: 82768 | F17: 6483 | G17: 0 | H17: 1008119
B18: 보험수익, 그 밖의 금액 | C18: 19120 | D18: 5408 | E18: 587 | F18: -1 | G18: 0 | H18: 25114
B19: 보험수익 | C19: 2053182 | D19: 2106945 | E19: 570393 | F19: 433054 | G19: 0 | H19: 5163574 | I19: 12103 | J19: 0 | K19: 0 | L19: 0 | M19: 0 | N19: 12103 | P19: =H19+N19 -> 5175677
A22: 발행보험의 보험서비스비용 분석 공시
A23: 당기 | B23: (단위 : 백만원)
B24: 보험계약의 세분
B25: 발행한 보험계약
B26: 보험계약
B27: 보험료배분접근법을 적용한 보험계약 외의 보험계약 | H27: 보험료배분접근법을 적용한 보험계약
B28: 계약의 유형 | G28: 계약의 유형 합계 | H28: 계약의 유형 | M28: 계약의 유형 합계
B29: 사망보험 | C29: 건강보험 | D29: 연금저축보험 | E29: 변액보험 | F29: 기타보험 | H29: 사망보험 | I29: 건강보험 | J29: 연금저축보험 | K29: 변액보험 | L29: 기타보험
A30: 보험서비스비용, 발생한 보험금 및 그 밖의 발생한 보험서비스비용 | B30: 1343042 | C30: 1479847 | D30: 303273 | E30: 514219 | F30: 283 | G30: 3640664
A31: 보험서비스비용, 보험취득 현금흐름의 상각에 따른 금액 | B31: 560559 | C31: 358308 | D31: 82768 | E31: 6484 | F31: 0 | G31: 1008119
A32: 보험서비스비용, 과거 서비스와 관련된 금액 | B32: -136982 | C32: 68145 | D32: -3091 | E32: -46596 | F32: 0 | G32: -118524
A33: 보험서비스비용, 미래 서비스와 관련된 변동분에 관련된 금액 | B33: 58524 | C33: 20511 | D33: -18806 | E33: 75343 | F33: 0 | G33: 135572
A34: 발행한 보험계약에서 생기는 보험서비스비용 | B34: 1825143 | C34: 1926811 | D34: 364144 | E34: 549450 | F34: 283 | G34: 4665831 | H34: 14070 | I34: 0 | J34: 0 | K34: 0 | L34: 0 | M34: 14070 | P34: =G34+M34 -> 4679901
A38: 발행보험의 보험서비스결과 분석 공시
A39: 당기 | B39: (단위 : 백만원)
B40: 보험계약의 세분
B41: 발행한 보험계약
B42: 계약의 유형 | G42: 계약의 유형 합계
B43: 사망보험 | C43: 건강보험 | D43: 연금저축보험 | E43: 변액보험 | F43: 기타보험
A44: 보험수익 | B44: 2065285 | C44: 2106945 | D44: 570393 | E44: 433054 | F44: 0 | G44: 5175677
A45: 발행한 보험계약에서 생기는 보험서비스비용 | B45: 1839213 | C45: 1926811 | D45: 364144 | E45: 549450 | F45: 283 | G45: 4679901
A46: 보험서비스결과 | B46: 226072 | C46: 180134 | D46: 206249 | E46: -116396 | F46: -283 | G46: 495776 | I46: =G46+E90 -> 491336 | P46: =P19-P34 -> 495776
A50: 23. 재보험서비스결과
...

Sheet 포괄손익계산서
A1: 4-2. 포괄손익계산서
A2: 포괄손익계산서
A3: 제 77 기 2025.01.01 부터 2025.12.31 까지
A4: 제 76 기 2024.01.01 부터 2024.12.31 까지
A5: 제 75 기 2023.01.01 부터 2023.12.31 까지
A6: (단위 : 백만원)
B7: 제 77 기 | C7: 제 76 기 | D7: 제 75 기
A8: 보험손익 | B8: 344419 | C8: 506305 | D8: 650941
A9: 보험영업수익 | B9: 5248088 | C9: 4921893 | D9: 4855905
A10: 보험수익 | B10: 5175677 | C10: 4864897 | D10: 4620054
A11: 재보험수익 | B11: 72411 | C11: 56996 | D11: 235851
A12: 보험서비스비용 | B12: 4903669 | C12: 4415588 | D12: 4204964
A13: 보험비용 | B13: 4679901 | C13: 4203414 | D13: 3825642
A14: 재보험비용 | B14: 76851 | C14: 66156 | D14: 233613
A15: 기타사업비용 | B15: 146917 | C15: 146018 | D15: 145709
A16: 투자손익 | B16: 57018 | C16: 76154 | D16: 15144
A17: 투자영업수익 | B17: 9226099 | C17: 8400250 | D17: 8365081
A18: 재보험금융수익 | B18: 10245 | C18: 4421 | D18: 3782
A19: 이자수익 | B19: 2673469 | C19: 2539255 | D19: 2633278
... A55: 총포괄손익 | B55: 256464 | C55: -1523073 | D55: 305015
A56: 주당이익(손실)
A57: 보통주기본주당이익 (단위 : 원) | B57: 262 | C57: 914 | D57: 766
A58: 보통주희석주당이익 (단위 : 원) | B58: 262 | C58: 914 | D58: 766
