Workbook

Sheet Sheet1
A1: 원보험사코드 | B1: 원수사명 | C1: 티커 | D1: 생손보여부 | E1: 항목번호 | F1: 항목명 | G1: 공시분기 | H1: 값 | I1: 검증
A2: KR0002 | B2: 한화손보 | D2: 손해보험 | E2: 1 | F2: 보험손익 | G2: 2024.2Q | H2: =H3+H14+H15+H16-H17 -> 262431.59 | I2: =ROUND(H2,0)=ROUND(206818.062,0) -> FALSE
A3: KR0002 | B3: 한화손보 | D3: 손해보험 | E3: =E2+1 -> 2 | F3: 생명장기 손익 | G3: 2024.2Q | H3: =H4+H9 -> 301239.9
A4: KR0002 | B4: 한화손보 | D4: 손해보험 | E4: =E3+1 -> 3 | F4: 생명장기 원수손익 | G4: 2024.2Q | H4: =(보험손익!F16-보험손익!F33)/1000 -> 315921.39
A5: KR0002 | B5: 한화손보 | D5: 손해보험 | E5: =E4+1 -> 4 | F5: 원수 CSM상각 | G5: 2024.2Q | H5: =보험손익!F13/1000 -> 205267.79
A6: KR0002 | B6: 한화손보 | D6: 손해보험 | E6: =E5+1 -> 5 | F6: 원수 위험조정 변동 | G6: 2024.2Q | H6: =보험손익!F12/1000 -> 38013.139
A7: KR0002 | B7: 한화손보 | D7: 손해보험 | E7: =E6+1 -> 6 | F7: 원수 예실차 | G7: 2024.2Q | H7: =(SUM(보험손익!F7:F10)-SUM(보험손익!F24:F25,보험손익!F27:F28))/1000 -> -49754.803
A8: KR0002 | B8: 한화손보 | D8: 손해보험 | E8: =E7+1 -> 7 | F8: 기타 생명장기 원수손익 | G8: 2024.2Q | H8: =H4-SUM(H5:H7) -> 122395.26
A9: KR0002 | B9: 한화손보 | D9: 손해보험 | E9: =E8+1 -> 8 | F9: 생명장기 재보험손익 | G9: 2024.2Q | H9: =(보험손익!F46-보험손익!F56)/1000 -> -14681.498
A10: KR0002 | B10: 한화손보 | D10: 손해보험 | E10: =E9+1 -> 9 | F10: 재보험 CSM상각 | G10: 2024.2Q | H10: =-보험손익!F50/1000 -> -1362.649
A11: KR0002 | B11: 한화손보 | D11: 손해보험 | E11: =E10+1 -> 10 | F11: 재보험 위험조정 변동 | G11: 2024.2Q | H11: =-보험손익!F51/1000 -> -694.771
A12: KR0002 | B12: 한화손보 | D12: 손해보험 | E12: =E11+1 -> 11 | F12: 재보험 예실차 | G12: 2024.2Q | H12: =(SUM(보험손익!F41:F42)-SUM(보험손익!F48:F49))/1000 -> -3736.487
A13: KR0002 | B13: 한화손보 | D13: 손해보험 | E13: =E12+1 -> 12 | F13: 기타 생명장기 재보험손익 | G13: 2024.2Q | H13: =H9-SUM(H10:H12) -> -8887.591
A14: KR0002 | B14: 한화손보 | D14: 손해보험 | E14: =E13+1 -> 13 | F14: 자동차손익 | G14: 2024.2Q | H14: =(보험손익!H16-보험손익!H33-보험손익!H56+보험손익!H46)/1000 -> 6738.548
A15: KR0002 | B15: 한화손보 | D15: 손해보험 | E15: =E14+1 -> 14 | F15: 일반손익 | G15: 2024.2Q | H15: =(보험손익!G16-보험손익!G33-보험손익!G56+보험손익!G46)/1000 -> 38971.408
A16: KR0002 | B16: 한화손보 | D16: 손해보험 | E16: =E15+1 -> 15 | F16: 기타영업수익 | G16: 2024.2Q
A17: KR0002 | B17: 한화손보 | D17: 손해보험 | E17: =E16+1 -> 16 | F17: 기타사업비용 | G17: 2024.2Q | H17: 84518.262
A18: KR0002 | B18: 한화손보 | D18: 손해보험 | E18: =E17+1 -> 17 | F18: 투자손익 | G18: 2024.2Q
A19: KR0002 | B19: 한화손보 | D19: 손해보험 | E19: =E18+1 -> 18 | F19: 투자이익 | G19: 2024.2Q
A20: KR0002 | B20: 한화손보 | D20: 손해보험 | E20: =E19+1 -> 19 | F20: 보험금융손익 | G20: 2024.2Q
A21: KR0002 | B21: 한화손보 | D21: 손해보험 | E21: =E20+1 -> 20 | F21: 영업이익 | G21: 2024.2Q
A22: KR0002 | B22: 한화손보 | D22: 손해보험 | E22: =E21+1 -> 21 | F22: 영업외손익 | G22: 2024.2Q
A23: KR0002 | B23: 한화손보 | D23: 손해보험 | E23: =E22+1 -> 22 | F23: 세전이익 | G23: 2024.2Q
A24: KR0002 | B24: 한화손보 | D24: 손해보험 | E24: =E23+1 -> 23 | F24: 법인세 | G24: 2024.2Q
A25: KR0002 | B25: 한화손보 | D25: 손해보험 | E25: =E24+1 -> 24 | F25: 당기순이익 | G25: 2024.2Q

Sheet 보험손익
A1: 26. 보험영업수익
A3: 당반기 및 전반기 중 발생한 보험영업수익 내역은 다음과 같습니다.
A4: (당반기) | B4: (단위: 천원)
A5: 항목 | B5: 3개월 | F5: 누 적
B6: 장 기 | C6: 일 반 | D6: 자동차 | E6: 합 계 | F6: 장 기 | G6: 일 반 | H6: 자동차 | I6: 합 계
A7: 예상보험금수익 | B7: 559732495 | C7: - | D7: - | E7: 559732495 | F7: 1115172304 | G7: - | H7: - | I7: 1115172304
A8: 예상손해조사비수익 | B8: 22723941 | C8: - | D8: - | E8: 22723941 | F8: 44920547 | G8: - | H8: - | I8: 44920547
A9: 예상계약유지비수익 | B9: 66783650 | C9: - | D9: - | E9: 66783650 | F9: 132332055 | G9: - | H9: - | I9: 132332055
A10: 예상투자관리비수익 | B10: 2649770 | C10: - | D10: - | E10: 2649770 | F10: 5252070 | G10: - | H10: - | I10: 5252070
A11: 보험취득현금흐름상각수익 | B11: 102310387 | C11: - | D11: - | E11: 102310387 | F11: 203366613 | G11: - | H11: - | I11: 203366613
A12: 위험조정변동수익 | B12: 19225474 | C12: - | D12: - | E12: 19225474 | F12: 38013139 | G12: - | H12: - | I12: 38013139
A13: 보험계약마진상각수익 | B13: 102564261 | C13: - | D13: - | E13: 102564261 | F13: 205267793 | G13: - | H13: - | I13: 205267793
A14: 손실요소배분 | B14: -8981885 | C14: - | D14: - | E14: -8981885 | F14: -19603778 | G14: - | H14: - | I14: -19603778
A15: 보험료배분접근법적용수익 | B15: - | C15: 172839028 | D15: 164353857 | E15: 337192885 | F15: - | G15: 332078833 | H15: 330932019 | I15: 663010852
A16: 합계 | B16: 867008093 | C16: 172839028 | D16: 164353857 | E16: 1204200978 | F16: 1724720743 | G16: 332078833 | H16: 330932019 | I16: 2387731595
A18: 27. 보험영업비용
A20: 당반기 및 전반기 중 발생한 보험영업비용 내역은 다음과 같습니다.
A21: (당반기) | B21: (단위: 천원)
A22: 항목 | B22: 3개월 | F22: 누 적
B23: 장 기 | C23: 일 반 | D23: 자동차 | E23: 합 계 | F23: 장 기 | G23: 일 반 | H23: 자동차 | I23: 합 계
A24: 발생보험금비용 | B24: 562740222 | C24: 81621561 | D24: 126469285 | E24: 770831068 | F24: 1174729109 | G24: 152053166 | H24: 253542667 | I24: 1580324942
A25: 발생손해조사비 | B25: 29245944 | C25: 5670684 | D25: 10477115 | E25: 45393743 | F25: 46030169 | G25: 12557046 | H25: 22941774 | I25: 81528989
A26: 발생사고부채변동비용 | B26: -25814033 | C26: -3670360 | D26: -7824152 | E26: -37308545 | F26: -120244562 | G26: -22122112 | H26: -9371830 | I26: -151738504
A27: 발생계약유지비용 | B27: 58973359 | C27: 5293839 | D27: 9786260 | E27: 74053458 | F27: 121461150 | G27: 10764789 | H27: 18985679 | I27: 151211618
A28: 발생투자관리비 | B28: 2129289 | C28: 15728 | D28: 35612 | E28: 2180629 | F28: 5211351 | G28: 34582 | H28: 53130 | I28: 5299063
A29: 보험취득현금흐름 상각비용 | B29: 102310387 | C29: 21566413 | D29: - | E29: 123876800 | F29: 203366613 | G29: 43446085 | H29: - | I29: 246812698
A30: 보험취득현금흐름 당기비용 | B30: - | C30: - | D30: 15553588 | E30: 15553588 | F30: - | G30: - | H30: 32641378 | I30: 32641378
A31: 손실부담계약관련비용(환입) | B31: 8437952 | C31: 821097 | D31: - | E31: 9259049 | F31: -4058757 | G31: 840970 | H31: -22 | I31: -3217809
A32: 기타보험영업비용 | B32: -12776064 | C32: 132570 | D32: - | E32: -12643494 | F32: -17695724 | G32: 155572 | H32: 848 | I32: -17539304
A33: 합계 | B33: 725247056 | C33: 111451532 | D33: 154497708 | E33: 991196296 | F33: 1408799349 | G33: 197730098 | H33: 318793624 | I33: 1925323071
A34: 28. 출재보험손익
A36: 당반기 및 전반기 중 발생한 출재보험수익 및 비용 내역은 다음과 같습니다.
A37: (당반기) | B37: (단위: 천원)
A38: 항목 | B38: 3개월 | F38: 누 적
B39: 장 기 | C39: 일 반 | D39: 자동차 | E39: 합 계 | F39: 장 기 | G39: 일 반 | H39: 자동차 | I39: 합 계
A40: 출재보험수익
A41: 발생출재보험금수익 | B41: 8847648 | C41: 30857315 | D41: 3624267 | E41: 43329230 | F41: 17021050 | G41: 60124733 | H41: 10333504 | I41: 87479287
A42: 발생수입손해조사비 | B42: -12943 | C42: 1363577 | D42: - | E42: 1350634 | F42: -2713 | G42: 2505812 | H42: - | I42: 2503099
A43: 출재발생사고부채변동수익 | B43: 461875 | C43: -5122052 | D43: -5768032 | E43: -10428209 | F43: -5404516 | G43: -24058196 | H43: -14065391 | I43: -43528103
A44: 손실회수요소 관련 이익(손실) | B44: -36339 | C44: -10973 | D44: - | E44: -47312 | F44: 1178517 | G44: -1089475 | H44: - | I44: 89042
...
