Workbook

Sheet Sheet1
A1: 원보험사코드 | B1: 원수사명 | C1: 티커 | D1: 생손보여부 | E1: 항목번호 | F1: 항목명 | G1: 공시분기 | H1: 값 | I1: 검증
A2: KR0008 | B2: 삼성화재 | D2: 손해보험 | E2: 1 | F2: 보험손익 | G2: 2025.2Q | H2: =H3+H14+H15+H16-H17 -> 935730.54 | I2: =ABS(ROUND(H2,0)-935730.895605)<2 -> TRUE
A3: KR0008 | B3: 삼성화재 | D3: 손해보험 | E3: =E2+1 -> 2 | F3: 생명장기 손익 | G3: 2025.2Q | H3: =H4+H9 -> 885716
A4: KR0008 | B4: 삼성화재 | D4: 손해보험 | E4: =E3+1 -> 3 | F4: 생명장기 원수손익 | G4: 2025.2Q | H4: =보험손익!D11-보험손익!D27 -> 904454
A5: KR0008 | B5: 삼성화재 | D5: 손해보험 | E5: =E4+1 -> 4 | F5: 원수 CSM상각 | G5: 2025.2Q | H5: =보험손익!D14 -> 812438
A6: KR0008 | B6: 삼성화재 | D6: 손해보험 | E6: =E5+1 -> 5 | F6: 원수 위험조정 변동 | G6: 2025.2Q | H6: =보험손익!D13 -> 91431
A7: KR0008 | B7: 삼성화재 | D7: 손해보험 | E7: =E6+1 -> 6 | F7: 원수 예실차 | G7: 2025.2Q | H7: =보험손익!D12-보험손익!D28 -> -91759
A8: KR0008 | B8: 삼성화재 | D8: 손해보험 | E8: =E7+1 -> 7 | F8: 기타 생명장기 원수손익 | G8: 2025.2Q | H8: =H4-SUM(H5:H7) -> 92344
A9: KR0008 | B9: 삼성화재 | D9: 손해보험 | E9: =E8+1 -> 8 | F9: 생명장기 재보험손익 | G9: 2025.2Q | H9: =-보험손익!D42+보험손익!D56 -> -18738
A10: KR0008 | B10: 삼성화재 | D10: 손해보험 | E10: =E9+1 -> 9 | F10: 재보험 CSM상각 | G10: 2025.2Q | H10: =-보험손익!D45 -> -23381
A11: KR0008 | B11: 삼성화재 | D11: 손해보험 | E11: =E10+1 -> 10 | F11: 재보험 위험조정 변동 | G11: 2025.2Q | H11: =-보험손익!D44 -> -8199
A12: KR0008 | B12: 삼성화재 | D12: 손해보험 | E12: =E11+1 -> 11 | F12: 재보험 예실차 | G12: 2025.2Q | H12: =-보험손익!D43+보험손익!D57 -> -30724
A13: KR0008 | B13: 삼성화재 | D13: 손해보험 | E13: =E12+1 -> 12 | F13: 기타 생명장기 재보험손익 | G13: 2025.2Q | H13: =H9-SUM(H10:H12) -> 43566
A14: KR0008 | B14: 삼성화재 | D14: 손해보험 | E14: =E13+1 -> 13 | F14: 자동차손익 | G14: 2025.2Q | H14: =보험손익!F11-보험손익!F27-보험손익!F42+보험손익!F56 -> 54948
A15: KR0008 | B15: 삼성화재 | D15: 손해보험 | E15: =E14+1 -> 14 | F15: 일반손익 | G15: 2025.2Q | H15: =보험손익!H11-보험손익!H27-보험손익!H42+보험손익!H56 -> 121091
A16: KR0008 | B16: 삼성화재 | D16: 손해보험 | E16: =E15+1 -> 15 | F16: 기타영업수익 | G16: 2025.2Q
A17: KR0008 | B17: 삼성화재 | D17: 손해보험 | E17: =E16+1 -> 16 | F17: 기타사업비용 | G17: 2025.2Q | H17: 126024.46
A18: KR0008 | B18: 삼성화재 | D18: 손해보험 | E18: =E17+1 -> 17 | F18: 투자손익 | G18: 2025.2Q
A19: KR0008 | B19: 삼성화재 | D19: 손해보험 | E19: =E18+1 -> 18 | F19: 투자이익 | G19: 2025.2Q
A20: KR0008 | B20: 삼성화재 | D20: 손해보험 | E20: =E19+1 -> 19 | F20: 보험금융손익 | G20: 2025.2Q
A21: KR0008 | B21: 삼성화재 | D21: 손해보험 | E21: =E20+1 -> 20 | F21: 영업이익 | G21: 2025.2Q
A22: KR0008 | B22: 삼성화재 | D22: 손해보험 | E22: =E21+1 -> 21 | F22: 영업외손익 | G22: 2025.2Q
A23: KR0008 | B23: 삼성화재 | D23: 손해보험 | E23: =E22+1 -> 22 | F23: 세전이익 | G23: 2025.2Q
A24: KR0008 | B24: 삼성화재 | D24: 손해보험 | E24: =E23+1 -> 23 | F24: 법인세 | G24: 2025.2Q
A25: KR0008 | B25: 삼성화재 | D25: 손해보험 | E25: =E24+1 -> 24 | F25: 당기순이익 | G25: 2025.2Q

Sheet 보험손익
A1: 25. 보험서비스결과
A4: 발행보험의 보험수익 분석 공시
A5: 당반기 | B5: (단위 : 백만원)
C6: 보험계약의 세분
C7: 발행한 보험계약
C8: 계약의 유형 | I8: 계약의 유형 합계
C9: 장기보험 | E9: 자동차보험 | G9: 일반보험
C10: 3개월 | D10: 누적 | E10: 3개월 | F10: 누적 | G10: 3개월 | H10: 누적 | I10: 3개월 | J10: 누적
A11: 보험수익 | C11: 2486201 | D11: 4958983 | E11: 1387876 | F11: 2765029 | G11: 676346 | H11: 1306378 | I11: 4550423 | J11: 9030390
A12: 보험수익 | B12: 보험수익, 보고기간에 발생한 보험서비스비용 (기초 예상 측정치) | C12: 1653517 | D12: 3269011 | E12: 0 | F12: 0 | G12: 0 | H12: 0 | I12: 1653517 | J12: 3269011
B13: 보험수익, 비금융위험에 대한 위험조정의 변동분 | C13: 46790 | D13: 91431 | E13: 0 | F13: 0 | G13: 0 | H13: 0 | I13: 46790 | J13: 91431
B14: 보험수익, 서비스의 이전으로 당기손익에 인식한 보험계약마진 | C14: 406417 | D14: 812438 | E14: 0 | F14: 0 | G14: 0 | H14: 0 | I14: 406417 | J14: 812438
B15: 보험수익, 보험취득 현금흐름의 회수와 관련되는 보험료 부분의 배분액 | C15: 388231 | D15: 792090 | E15: 0 | F15: 0 | G15: 0 | H15: 0 | I15: 388231 | J15: 792090
B16: 보험수익, 그 밖의 금액 | C16: -8754 | D16: -5987 | E16: 0 | F16: 0 | G16: 0 | H16: 0 | I16: -8754 | J16: -5987
B17: 총 보험수익, 잔여보장부채의 변동분과 관련되는 금액 | C17: 0 | D17: 0 | E17: 1387876 | F17: 2765029 | G17: 676346 | H17: 1306378 | I17: 2064222 | J17: 4071407
A20: 발행보험의 보험서비스비용 분석 공시
A21: 당반기 | B21: (단위 : 백만원)
C22: 보험계약의 세분
C23: 발행한 보험계약
C24: 계약의 유형 | I24: 계약의 유형 합계
C25: 장기보험 | E25: 자동차보험 | G25: 일반보험
C26: 3개월 | D26: 누적 | E26: 3개월 | F26: 누적 | G26: 3개월 | H26: 누적 | I26: 3개월 | J26: 누적
A27: 발행한 보험계약에서 생기는 보험서비스비용 | C27: 2017147 | D27: 4054529 | E27: 1369984 | F27: 2710112 | G27: 472033 | H27: 1138960 | I27: 3859164 | J27: 7903601
A28: 발행한 보험계약에서 생기는 보험서비스비용 | B28: 보험서비스비용, 발생한 보험금 및 그 밖의 발생한 보험서비스비용 | C28: 1677688 | D28: 3360770 | E28: 1276198 | F28: 2575421 | G28: 383882 | H28: 735950 | I28: 3337768 | J28: 6672141
B29: 보험서비스비용, 과거 서비스와 관련된 금액 | C29: -52182 | D29: -100829 | E29: -14954 | F29: -78791 | G29: 33397 | H29: 300069 | I29: -33739 | J29: 120449
B30: 보험서비스비용, 미래 서비스와 관련된 변동분에 관련된 금액 | C30: 3410 | D30: 2498 | E30: 0 | F30: 0 | G30: 71 | H30: -2930 | I30: 3481 | J30: -432
B31: 보험서비스비용, 보험취득 현금흐름의 상각에 따른 금액 | C31: 388231 | D31: 792090 | E31: 108740 | F31: 213482 | G31: 54683 | H31: 105871 | I31: 551654 | J31: 1111443
A33: 26. 재보험서비스결과
A35: 재보험비용 분석 공시
A36: 당반기 | B36: (단위 : 백만원)
C37: 보험계약의 세분
C38: 보유 재보험계약
C39: 계약의 유형 | I39: 계약의 유형 합계
C40: 장기보험 | E40: 자동차보험 | G40: 일반보험
C41: 3개월 | D41: 누적 | E41: 3개월 | F41: 누적 | G41: 3개월 | H41: 누적 | I41: 3개월 | J41: 누적
A42: 재보험자에게 지급된 보험료 배분액에서 생기는 비용 | C42: 74598 | D42: 92450 | E42: 0 | F42: 0 | G42: 238870 | H42: 459046 | I42: 313468 | J42: 551496
A43: 재보험자에게 지급된 보험료 배분액에서 생기는 비용 | B43: 재보험비용, 보고기간에 발생한 보험서비스비용 (기초 예상 측정치) | C43: 56694 | D43: 114624 | E43: 0 | F43: 0 | G43: 0 | H43: 0 | I43: 56694 | J43: 114624
B44: 재보험비용, 비금융위험에 대한 위험조정의 변동분 | C44: 3824 | D44: 8199 | E44: 0 | F44: 0 | G44: 0 | H44: 0 | I44: 3824 | J44: 8199
B45: 재보험비용, 서비스의 이전으로 당기손익에 인식한 보험계약마진 | C45: 11670 | D45: 23381 | E45: 0 | F45: 0 | G45: 0 | H45: 0 | I45: 11670 | J45: 23381
B46: 재보험비용, 그 밖의 금액 | C46: 2255 | D46: -54079 | E46: 0 | F46: 0 | G46: 0 | H46: 0 | I46: 2255 | J46: -54079
...
