Workbook

Sheet Sheet1
A1: 원보험사코드 | B1: 원수사명 | C1: 티커 | D1: 생손보여부 | E1: 항목번호 | F1: 항목명 | G1: 공시분기 | H1: 값 | I1: 검증
A2: KR0005 | B2: 흥국화재 | D2: 손해보험 | E2: 1 | F2: 보험손익 | G2: 2024.2Q | H2: =H3+H14+H15+H16-H17 -> 182019 | I2: =ABS(ROUND(H2,0)-1135414.928)<2 -> FALSE
A3: KR0005 | B3: 흥국화재 | D3: 손해보험 | E3: =E2+1 -> 2 | F3: 생명장기 손익 | G3: 2024.2Q | H3: =H4+H9 -> 183564
A4: KR0005 | B4: 흥국화재 | D4: 손해보험 | E4: =E3+1 -> 3 | F4: 생명장기 원수손익 | G4: 2024.2Q | H4: =보험손익!B21-보험손익!B41 -> 186716
A5: KR0005 | B5: 흥국화재 | D5: 손해보험 | E5: =E4+1 -> 4 | F5: 원수 CSM상각 | G5: 2024.2Q | H5: =보험손익!B16 -> 114554
A6: KR0005 | B6: 흥국화재 | D6: 손해보험 | E6: =E5+1 -> 5 | F6: 원수 위험조정 변동 | G6: 2024.2Q | H6: =보험손익!B15 -> 15370
A7: KR0005 | B7: 흥국화재 | D7: 손해보험 | E7: =E6+1 -> 6 | F7: 원수 예실차 | G7: 2024.2Q | H7: =SUM(보험손익!B10)-보험손익!B33-보험손익!B36-보험손익!B38-보험손익!B37 -> 62769
A8: KR0005 | B8: 흥국화재 | D8: 손해보험 | E8: =E7+1 -> 7 | F8: 기타 생명장기 원수손익 | G8: 2024.2Q | H8: =H4-SUM(H5:H7) -> -5977
A9: KR0005 | B9: 흥국화재 | D9: 손해보험 | E9: =E8+1 -> 8 | F9: 생명장기 재보험손익 | G9: 2024.2Q | H9: =+보험손익!B70+보험손익!B81-보험손익!B101 -> -3152
A10: KR0005 | B10: 흥국화재 | D10: 손해보험 | E10: =E9+1 -> 9 | F10: 재보험 CSM상각 | G10: 2024.2Q | H10: =-보험손익!B97 -> 7798
A11: KR0005 | B11: 흥국화재 | D11: 손해보험 | E11: =E10+1 -> 10 | F11: 재보험 위험조정 변동 | G11: 2024.2Q | H11: =-보험손익!B96 -> -751
A12: KR0005 | B12: 흥국화재 | D12: 손해보험 | E12: =E11+1 -> 11 | F12: 재보험 예실차 | G12: 2024.2Q | H12: =보험손익!B78+보험손익!B66+보험손익!B67+N(보험손익!B79)-N(보험손익!B94)-N(보험손익!B95) -> -8852
A13: KR0005 | B13: 흥국화재 | D13: 손해보험 | E13: =E12+1 -> 12 | F13: 기타 생명장기 재보험손익 | G13: 2024.2Q | H13: =H9-SUM(H10:H12) -> -1347
A14: KR0005 | B14: 흥국화재 | D14: 손해보험 | E14: =E13+1 -> 13 | F14: 자동차손익 | G14: 2024.2Q | H14: =보험손익!D21-보험손익!C54+보험손익!D81-보험손익!D101 -> -3671
A15: KR0005 | B15: 흥국화재 | D15: 손해보험 | E15: =E14+1 -> 14 | F15: 일반손익 | G15: 2024.2Q | H15: =보험손익!C21-보험손익!B54+보험손익!C81-보험손익!C101 -> 2126
A16: KR0005 | B16: 흥국화재 | D16: 손해보험 | E16: =E15+1 -> 15 | F16: 기타영업수익 | G16: 2024.2Q
A17: KR0005 | B17: 흥국화재 | D17: 손해보험 | E17: =E16+1 -> 16 | F17: 기타사업비용 | G17: 2024.2Q | I17: <- 흥국화재도 기타사업비 안빼야 보험손익 일치
A18: KR0005 | B18: 흥국화재 | D18: 손해보험 | E18: =E17+1 -> 17 | F18: 투자손익 | G18: 2024.2Q
A19: KR0005 | B19: 흥국화재 | D19: 손해보험 | E19: =E18+1 -> 18 | F19: 투자이익 | G19: 2024.2Q
A20: KR0005 | B20: 흥국화재 | D20: 손해보험 | E20: =E19+1 -> 19 | F20: 보험금융손익 | G20: 2024.2Q
A21: KR0005 | B21: 흥국화재 | D21: 손해보험 | E21: =E20+1 -> 20 | F21: 영업이익 | G21: 2024.2Q
A22: KR0005 | B22: 흥국화재 | D22: 손해보험 | E22: =E21+1 -> 21 | F22: 영업외손익 | G22: 2024.2Q
A23: KR0005 | B23: 흥국화재 | D23: 손해보험 | E23: =E22+1 -> 22 | F23: 세전이익 | G23: 2024.2Q
A24: KR0005 | B24: 흥국화재 | D24: 손해보험 | E24: =E23+1 -> 23 | F24: 법인세 | G24: 2024.2Q
A25: KR0005 | B25: 흥국화재 | D25: 손해보험 | E25: =E24+1 -> 24 | F25: 당기순이익 | G25: 2024.2Q

Sheet 보험손익
A1: 28. 보험수익
A3: 당반기와 전반기의 보험종류별 보험수익 내역은 다음과 같습니다.
A5: <제79(당)기 반기 누적>
A6: (단위: 백만원)
A7: 구 분 | B7: 장기 | C7: 일반 | D7: 자동차 | E7: 합 계
A8: <보험료배분접근법을 적용하지 않는 발행한 보험계약>
A9: 잔여보장부채의 변동과 관련된 금액 | B9: 1036304 | C9: - | D9: - | E9: 1036304
A10: 예상 발생한 보험서비스비용 | B10: 906380 | C10: - | D10: - | E10: 906380
A11: 예상지급보험금 | B11: 808370 | C11: - | D11: - | E11: 808370
A12: 예상직접유지비 | B12: 62087 | C12: - | D12: - | E12: 62087
A13: 예상투자관리비 | B13: 4192 | C13: - | D13: - | E13: 4192
A14: 예상손해조사비 | B14: 31731 | C14: - | D14: - | E14: 31731
A15: 비금융위험에 대한 위험조정 변동 | B15: 15370 | C15: - | D15: - | E15: 15370
A16: 보험계약마진상각 | B16: 114554 | C16: - | D16: - | E16: 114554
A17: 보험인수현금흐름의 회수와 관련된 보험료 부분의 배분액 | B17: 89490 | C17: - | D17: - | E17: 89490
A18: 소 계 | B18: 1125794 | C18: - | D18: - | E18: 1125794
A19: <보험료배분접근법을 적용하는 보험계약>
A20: 보험료배분법적용수익 | B20: - | C20: 66672 | D20: 56913 | E20: 123585
A21: 합 계 | B21: 1125794 | C21: 66672 | D21: 56913 | E21: 1249379
A24: 29. 보험서비스비용
A26: 당반기 및 전반기 중 보험서비스비용의 내역은 다음과 같습니다.
A28: (1) 일반모형적용계약
A30: <제79(당)기 반기 누적>
A31: (단위: 백만원)
A32: 구분 | B32: 장기 | C32: 합계
A33: 발생보험금 | B33: 742429 | C33: 742429
A34: 발생사고부채변동 | B34: 2370 | C34: 2370
A35: 직접신계약비상각비 | B35: 89650 | C35: 89650
A36: 직접유지비 | B36: 64343 | C36: 64343
A37: 손해조사비 | B37: 32631 | C37: 32631
A38: 투자관리비 | B38: 4208 | C38: 4208
A39: 손실부담계약집합의 손실 (손실의 환입) | B39: -6332 | C39: -6332
A40: 기타보험서비스비용 | B40: 9779 | C40: 9779
A41: 합 계 | B41: 939078 | C41: 939078
A42: (2) 보험료배분접근법적용계약
A44: <제79(당)기 반기 누적>
A45: (단위: 백만원)
A46: 구분 | B46: 일반 | C46: 자동차 | D46: 합계
A47: 발생보험금 | B47: 16399 | C47: 50076 | D47: 66475
A48: 발생사고부채변동 | B48: 6616 | C48: -6261 | D48: 355
...
