Workbook

Sheet Sheet1
A1: 원보험사코드 | B1: 원수사명 | C1: 티커 | D1: 생손보여부 | E1: 항목번호 | F1: 항목명 | G1: 공시분기 | H1: 값 | I1: 검증
A2: KR0002 | B2: 한화손보 | D2: 손해보험 | E2: 1 | F2: 보험손익 | G2: 2025.4Q | H2: =H3+H14+H15+H16-H17 -> 206818.06 | I2: =ROUND(H2,0)=ROUND(206818.062,0) -> TRUE
A3: KR0002 | B3: 한화손보 | D3: 손해보험 | E3: =E2+1 -> 2 | F3: 생명장기 손익 | G3: 2025.4Q | H3: =H4+H9 -> 252199.57
A4: KR0002 | B4: 한화손보 | D4: 손해보험 | E4: =E3+1 -> 3 | F4: 생명장기 원수손익 | G4: 2025.4Q | H4: =(보험손익!C24-보험손익!C46)/1000 -> 250696.9
A5: KR0002 | B5: 한화손보 | D5: 손해보험 | E5: =E4+1 -> 4 | F5: 원수 CSM상각 | G5: 2025.4Q | H5: =보험손익!C20/1000 -> 210229.26
A6: KR0002 | B6: 한화손보 | D6: 손해보험 | E6: =E5+1 -> 5 | F6: 원수 위험조정 변동 | G6: 2025.4Q | H6: =보험손익!C19/1000 -> 38443.861
A7: KR0002 | B7: 한화손보 | D7: 손해보험 | E7: =E6+1 -> 6 | F7: 원수 예실차 | G7: 2025.4Q | H7: =(보험손익!C14+보험손익!C15+보험손익!C16+보험손익!C17-보험손익!C35-보험손익!C36-보험손익!C38-보험손익!C39)/1000 -> -45928.987
A8: KR0002 | B8: 한화손보 | D8: 손해보험 | E8: =E7+1 -> 7 | F8: 기타 생명장기 원수손익 | G8: 2025.4Q | H8: =H4-SUM(H5:H7) -> 47952.762
A9: KR0002 | B9: 한화손보 | D9: 손해보험 | E9: =E8+1 -> 8 | F9: 생명장기 재보험손익 | G9: 2025.4Q | H9: =(SUM(보험손익!C60:C65,보험손익!K60:K65)-SUM(보험손익!C76:C83,보험손익!K76:K83))/1000 -> 1502.675
A10: KR0002 | B10: 한화손보 | D10: 손해보험 | E10: =E9+1 -> 9 | F10: 재보험 CSM상각 | G10: 2025.4Q | H10: =-보험손익!C78/1000 -> -4846.076
A11: KR0002 | B11: 한화손보 | D11: 손해보험 | E11: =E10+1 -> 10 | F11: 재보험 위험조정 변동 | G11: 2025.4Q | H11: =-보험손익!C79/1000 -> -681.197
A12: KR0002 | B12: 한화손보 | D12: 손해보험 | E12: =E11+1 -> 11 | F12: 재보험 예실차 | G12: 2025.4Q | H12: =(SUM(보험손익!C60:C61,보험손익!K60:K61)-SUM(보험손익!C76:C77,보험손익!K76:K77))/1000 -> 3590.791
A13: KR0002 | B13: 한화손보 | D13: 손해보험 | E13: =E12+1 -> 12 | F13: 기타 생명장기 재보험손익 | G13: 2025.4Q | H13: =H9-SUM(H10:H12) -> 3439.157
A14: KR0002 | B14: 한화손보 | D14: 손해보험 | E14: =E13+1 -> 13 | F14: 자동차손익 | G14: 2025.4Q | H14: =(보험손익!M24-보험손익!M46-SUM(보험손익!O82:O83)+SUM(보험손익!O60:O65))/1000 -> -5650.034
A15: KR0002 | B15: 한화손보 | D15: 손해보험 | E15: =E14+1 -> 14 | F15: 일반손익 | G15: 2025.4Q | H15: =(보험손익!K24-보험손익!K46-SUM(보험손익!M82:M83)+SUM(보험손익!M60:M65))/1000 -> 18664.691
A16: KR0002 | B16: 한화손보 | D16: 손해보험 | E16: =E15+1 -> 15 | F16: 기타영업수익 | G16: 2025.4Q
A17: KR0002 | B17: 한화손보 | D17: 손해보험 | E17: =E16+1 -> 16 | F17: 기타사업비용 | G17: 2025.4Q | H17: 58396.167
A18: KR0002 | B18: 한화손보 | D18: 손해보험 | E18: =E17+1 -> 17 | F18: 투자손익 | G18: 2025.4Q
A19: KR0002 | B19: 한화손보 | D19: 손해보험 | E19: =E18+1 -> 18 | F19: 투자이익 | G19: 2025.4Q
A20: KR0002 | B20: 한화손보 | D20: 손해보험 | E20: =E19+1 -> 19 | F20: 보험금융손익 | G20: 2025.4Q
A21: KR0002 | B21: 한화손보 | D21: 손해보험 | E21: =E20+1 -> 20 | F21: 영업이익 | G21: 2025.4Q
A22: KR0002 | B22: 한화손보 | D22: 손해보험 | E22: =E21+1 -> 21 | F22: 영업외손익 | G22: 2025.4Q
A23: KR0002 | B23: 한화손보 | D23: 손해보험 | E23: =E22+1 -> 22 | F23: 세전이익 | G23: 2025.4Q
A24: KR0002 | B24: 한화손보 | D24: 손해보험 | E24: =E23+1 -> 23 | F24: 법인세 | G24: 2025.4Q
A25: KR0002 | B25: 한화손보 | D25: 손해보험 | E25: =E24+1 -> 24 | F25: 당기순이익 | G25: 2025.4Q

Sheet 보험손익
A2: 22. 보험손익
A4: 발행보험의 보험수익 분석 공시
A5: 발행보험의 보험수익 분석 공시
A6: 당반기 | B6: (단위 : 천원)
B7: 보험계약의 세분
B8: 발행한 보험계약
B9: 보험계약 | N9: 보험계약 합계
B10: 보험료배분접근법을 적용한 보험계약 외의 보험계약 | H10: 보험료배분접근법을 적용한 보험계약
B11: 계약의 유형
B12: 장기보험 | D12: 일반보험 | F12: 자동차보험 | H12: 장기보험 | J12: 일반보험 | L12: 자동차보험
B13: 3개월 | C13: 누적 | D13: 3개월 | E13: 누적 | F13: 3개월 | G13: 누적 | H13: 3개월 | I13: 누적 | J13: 3개월 | K13: 누적 | L13: 3개월 | M13: 누적 | N13: 3개월 | O13: 누적
A14: 보험수익, 예상 보험금 (기초 예상 측정치) | B14: 622220672 | C14: 1234844286 | J14: 0 | K14: 0 | L14: 0 | M14: 0 | N14: 622220672 | O14: 1234844286
A15: 보험수익, 예상 손해조사비 (기초 예상 측정치) | B15: 24540842 | C15: 48944885 | J15: 0 | K15: 0 | L15: 0 | M15: 0 | N15: 24540842 | O15: 48944885
A16: 보험수익, 예상 유지비 (기초 예상 측정치) | B16: 72133356 | C16: 142875633 | J16: 0 | K16: 0 | L16: 0 | M16: 0 | N16: 72133356 | O16: 142875633
A17: 보험수익, 예상 투자관리비 (기초 예상 측정치) | B17: 2735807 | C17: 5437189 | J17: 0 | K17: 0 | L17: 0 | M17: 0 | N17: 2735807 | O17: 5437189
A18: 보험수익, 보험취득 현금흐름의 회수와 관련되는 보험료 부분의 배분액 | B18: 132490299 | C18: 265117257 | J18: 0 | K18: 0 | L18: 0 | M18: 0 | N18: 132490299 | O18: 265117257
A19: 보험수익, 비금융위험에 대한 위험조정의 변동분 | B19: 19153058 | C19: 38443861 | J19: 0 | K19: 0 | L19: 0 | M19: 0 | N19: 19153058 | O19: 38443861
A20: 보험수익, 서비스의 이전으로 당기손익에 인식한 보험계약마진 | B20: 105506757 | C20: 210229261 | J20: 0 | K20: 0 | L20: 0 | M20: 0 | N20: 105506757 | O20: 210229261
A21: 보험수익, 손실요소배분 | B21: -9866351 | C21: -21024145 | J21: 0 | K21: 0 | L21: 0 | M21: 0 | N21: -9866351 | O21: -21024145
A22: 보험수익, 보험료배분접근법적용계약에서 발생한 수익 | B22: 0 | C22: 0 | J22: 193543706 | K22: 364306283 | L22: 160518975 | M22: 318448463 | N22: 354062681 | O22: 682754746
A23: 보험수익, 그 밖의 금액 | B23: 0 | C23: 2970 | J23: 0 | K23: 0 | L23: 0 | M23: -270 | N23: 0 | O23: 2700
A24: 보험수익 | B24: 968914440 | C24: 1924871197 | J24: 193543706 | K24: 364306283 | L24: 160518975 | M24: 318448193 | N24: 1322977121 | O24: 2607625673
A26: 발행보험의 보험서비스비용 분석 공시
A27: 당반기 | B27: (단위 : 천원)
B28: 보험계약의 세분
B29: 발행한 보험계약
B30: 보험계약 | N30: 보험계약 합계
B31: 보험료배분접근법을 적용한 보험계약 외의 보험계약 | H31: 보험료배분접근법을 적용한 보험계약
B32: 계약의 유형
B33: 장기보험 | D33: 일반보험 | F33: 자동차보험 | H33: 장기보험 | J33: 일반보험 | L33: 자동차보험
B34: 3개월 | C34: 누적 | D34: 3개월 | E34: 누적 | F34: 3개월 | G34: 누적 | H34: 3개월 | I34: 누적 | J34: 3개월 | K34: 누적 | L34: 3개월 | M34: 누적 | N34: 3개월 | O34: 누적
A35: 보험서비스비용, 발생한 보험금 | B35: 637300139 | C35: 1286746614 | J35: 139420238 | K35: 220843942 | L35: 123908201 | M35: 248359928 | N35: 900628578 | O35: 1755950484
A36: 보험서비스비용, 발생한 손해조사비 | B36: 23607352 | C36: 47828820 | J36: 7950274 | K36: 13766875 | L36: 12222266 | M36: 23342006 | N36: 43779892 | O36: 84937701
A37: 보험서비스비용, 과거 서비스와 관련된 금액 | B37: 10086070 | C37: -12086559 | J37: 8452944 | K37: 17160223 | L37: -2481711 | M37: -8890837 | N37: 16057303 | O37: -3817173
A38: 보험서비스비용, 발생한 유지비 | B38: 68701040 | C38: 137323386 | J38: 5687512 | K38: 10783002 | L38: 9650709 | M38: 19309045 | N38: 84039261 | O38: 167415433
A39: 보험서비스비용, 발생한 투자관리비 | B39: 2748919 | C39: 6132160 | J39: 22636 | K39: 50955 | L39: 47258 | M39: 108092 | N39: 2818813 | O39: 6291207
A40: 보험서비스비용, 보험취득 현금흐름의 상각에 따른 금액 | B40: 132490299 | C40: 265117257 | J40: 23568569 | K40: 47426033 | L40: 0 | M40: 0 | N40: 156058868 | O40: 312543290
A41: 보험서비스비용, 보험취득 현금흐름에서 발생한 비용 | B41: 0 | C41: 0 | J41: 0 | K41: 0 | L41: 20387281 | M41: 40413470 | N41: 20387281 | O41: 40413470
A42: 보험서비스비용, 당기 및 과거서비스 보험료 경험조정 | B42: -2684493 | C42: -8426388 | J42: 0 | K42: 0 | L42: 0 | M42: 0 | N42: -2684493 | O42: -8426388
A43: 보험서비스비용, 손실요소배분 | B43: -9866351 | C43: -21024145 | J43: 0 | K43: 0 | L43: 0 | M43: 0 | N43: -9866351 | O43: -21024145
...
