Workbook

Sheet Sheet1
A1: 원보험사코드 | B1: 원수사명 | C1: 티커 | D1: 생손보여부 | E1: 항목번호 | F1: 항목명 | G1: 공시분기 | H1: 값 | I1: 검증
A2: KR0011 | B2: DB손보 | D2: 손해보험 | E2: 1 | F2: 보험손익 | G2: 2024.4Q | H2: =H3+H14+H15+H16-H17 -> 1619094.5 | I2: =ABS(ROUND(H2,0)-1619094)<2 -> TRUE
A3: KR0011 | B3: DB손보 | D3: 손해보험 | E3: =E2+1 -> 2 | F3: 생명장기 손익 | G3: 2024.4Q | H3: =H4+H9 -> 1419675
A4: KR0011 | B4: DB손보 | D4: 손해보험 | E4: =E3+1 -> 3 | F4: 생명장기 원수손익 | G4: 2024.4Q | H4: =N(보험손익!B19)-N(보험손익!B44) -> 1486688
A5: KR0011 | B5: DB손보 | D5: 손해보험 | E5: =E4+1 -> 4 | F5: 원수 CSM상각 | G5: 2024.4Q | H5: =보험손익!B13 -> 1297508
A6: KR0011 | B6: DB손보 | D6: 손해보험 | E6: =E5+1 -> 5 | F6: 원수 위험조정 변동 | G6: 2024.4Q | H6: =보험손익!B12 -> 135863
A7: KR0011 | B7: DB손보 | D7: 손해보험 | E7: =E6+1 -> 6 | F7: 원수 예실차 | G7: 2024.4Q | H7: =보험손익!B7+보험손익!B9+보험손익!B10+보험손익!B11-보험손익!B25-보험손익!B28-보험손익!B29-보험손익!B30 -> -3242
A8: KR0011 | B8: DB손보 | D8: 손해보험 | E8: =E7+1 -> 7 | F8: 기타 생명장기 원수손익 | G8: 2024.4Q | H8: =H4-SUM(H5:H7) -> 56559
A9: KR0011 | B9: DB손보 | D9: 손해보험 | E9: =E8+1 -> 8 | F9: 생명장기 재보험손익 | G9: 2024.4Q | H9: =보험손익!B56-보험손익!B69 -> -67013
A10: KR0011 | B10: DB손보 | D10: 손해보험 | E10: =E9+1 -> 9 | F10: 재보험 CSM상각 | G10: 2024.4Q | H10: =-보험손익!B65 -> -10861
A11: KR0011 | B11: DB손보 | D11: 손해보험 | E11: =E10+1 -> 10 | F11: 재보험 위험조정 변동 | G11: 2024.4Q | H11: =-보험손익!B64 -> -3845
A12: KR0011 | B12: DB손보 | D12: 손해보험 | E12: =E11+1 -> 11 | F12: 재보험 예실차 | G12: 2024.4Q | H12: =보험손익!B50+보험손익!B51-보험손익!B62-보험손익!B63 -> -67233
A13: KR0011 | B13: DB손보 | D13: 손해보험 | E13: =E12+1 -> 12 | F13: 기타 생명장기 재보험손익 | G13: 2024.4Q | H13: =H9-SUM(H10:H12) -> 14926
A14: KR0011 | B14: DB손보 | D14: 손해보험 | E14: =E13+1 -> 13 | F14: 자동차손익 | G14: 2024.4Q | H14: =보험손익!D19-보험손익!D44-보험손익!D69+보험손익!D56 -> 192061
A15: KR0011 | B15: DB손보 | D15: 손해보험 | E15: =E14+1 -> 14 | F15: 일반손익 | G15: 2024.4Q | H15: =보험손익!C19-보험손익!C44-보험손익!C69+보험손익!C56 -> 117480
A16: KR0011 | B16: DB손보 | D16: 손해보험 | E16: =E15+1 -> 15 | F16: 기타영업수익 | G16: 2024.4Q
A17: KR0011 | B17: DB손보 | D17: 손해보험 | E17: =E16+1 -> 16 | F17: 기타사업비용 | G17: 2024.4Q | H17: 110121.52
A18: KR0011 | B18: DB손보 | D18: 손해보험 | E18: =E17+1 -> 17 | F18: 투자손익 | G18: 2024.4Q
A19: KR0011 | B19: DB손보 | D19: 손해보험 | E19: =E18+1 -> 18 | F19: 투자이익 | G19: 2024.4Q
A20: KR0011 | B20: DB손보 | D20: 손해보험 | E20: =E19+1 -> 19 | F20: 보험금융손익 | G20: 2024.4Q
A21: KR0011 | B21: DB손보 | D21: 손해보험 | E21: =E20+1 -> 20 | F21: 영업이익 | G21: 2024.4Q
A22: KR0011 | B22: DB손보 | D22: 손해보험 | E22: =E21+1 -> 21 | F22: 영업외손익 | G22: 2024.4Q
A23: KR0011 | B23: DB손보 | D23: 손해보험 | E23: =E22+1 -> 22 | F23: 세전이익 | G23: 2024.4Q
A24: KR0011 | B24: DB손보 | D24: 손해보험 | E24: =E23+1 -> 23 | F24: 법인세 | G24: 2024.4Q
A25: KR0011 | B25: DB손보 | D25: 손해보험 | E25: =E24+1 -> 24 | F25: 당기순이익 | G25: 2024.4Q

Sheet 보험손익
A1: 6. 보험수익 및 비용과 재보험수익 및 비용
A3: 6-1 당기 및 전기 중 발행한 보험계약의 보험수익은 다음과 같습니다.
A4: <당기> | B4: (단위: 백만원)
A5: 구 분 | B5: 장 기 | C5: 일 반 | D5: 자동차 | E5: 합 계
A6: <원수>
A7: 예상보험금 | B7: 4810591 | C7: - | D7: - | E7: 4810591
A8: 보험취득현금흐름상각 | B8: 1607902 | C8: - | D8: - | E8: 1607902
A9: 예상유지비 | B9: 428648 | C9: - | D9: - | E9: 428648
A10: 예상손해조사비 | B10: 194417 | C10: - | D10: - | E10: 194417
A11: 예상투자관리비 | B11: 26729 | C11: - | D11: - | E11: 26729
A12: 비금융위험에 대한 위험조정상각 | B12: 135863 | C12: - | D12: - | E12: 135863
A13: 보험계약마진상각 | B13: 1297508 | C13: - | D13: - | E13: 1297508
A14: 손실요소배분 | B14: -97495 | C14: - | D14: - | E14: -97495
A15: 보험료배분접근법적용계약 발생수익 | B15: - | C15: 2015556 | D15: 4220832 | E15: 6236388
A16: 소 계 | B16: 8404163 | C16: 2015556 | D16: 4220832 | E16: 14640551
A17: <수재>
A18: 보험료배분접근법적용계약 발생수익 | B18: - | C18: 115575 | D18: - | E18: 115575
A19: 합 계 | B19: 8404163 | C19: 2131131 | D19: 4220832 | E19: 14756126
A21: 6-2 당기 및 전기의 발행한 보험계약의 보험비용은 다음과 같습니다.
A22: <당기> | B22: (단위: 백만원)
A23: 구 분 | B23: 장 기 | C23: 일 반 | D23: 자동차 | E23: 합 계
A24: <원수>
A25: 발생보험금 | B25: 4767571 | C25: 1144072 | D25: 3255468 | E25: 9167111
A26: 보험취득현금흐름상각 | B26: 1607902 | C26: 366422 | D26: - | E26: 1974324
A27: 보험취득현금흐름비용 | B27: - | C27: 4720 | D27: 443019 | E27: 447739
A28: 발생직접유지비 | B28: 452628 | C28: 41054 | D28: 159651 | E28: 653333
A29: 손해조사비 | B29: 228519 | C29: 155724 | D29: 284614 | E29: 668857
A30: 투자관리비 | B30: 14909 | C30: - | D30: - | E30: 14909
A31: 손실부담계약의 손실인식(환입) | B31: 118611 | C31: 1242 | D31: 39 | E31: 119892
A32: 발생사고부채 조정 | B32: -176889 | C32: -327771 | D32: -113483 | E32: -618143
A33: 손실요소배분 | B33: -97495 | C33: - | D33: - | E33: -97495
A34: 보험취득현금흐름 경험조정 | B34: 1719 | C34: - | D34: - | E34: 1719
A35: 소 계 | B35: 6917475 | C35: 1385463 | D35: 4029308 | E35: 12332246
A36: <수재>
A37: 발생수재보험금 | B37: - | C37: 337285 | D37: - | E37: 337285
A38: 수재손해조사비 | B38: - | C38: 558 | D38: - | E38: 558
A39: 수재이익수수료 | B39: - | C39: 644 | D39: - | E39: 644
A40: 수재유지비 | B40: - | C40: 216 | D40: - | E40: 216
A41: 손실부담계약의 손실인식(환입) | B41: - | C41: -362 | D41: - | E41: -362
A42: 발생사고부채 조정 | B42: - | C42: -249903 | D42: - | E42: -249903
...
