Workbook

Sheet Sheet1
A1: 원보험사코드 | B1: 원수사명 | C1: 티커 | D1: 생손보여부 | E1: 항목번호 | F1: 항목명 | G1: 공시분기 | H1: 값 | I1: 검증
A2: KR0011 | B2: DB손보 | D2: 손해보험 | E2: 1 | F2: 보험손익 | G2: 2025.2Q | H2: =H3+H14+H15+H16-H17 -> 670412 | I2: =ABS(ROUND(H2,0)-670411)<2 -> TRUE
A3: KR0011 | B3: DB손보 | D3: 손해보험 | E3: =E2+1 -> 2 | F3: 생명장기 손익 | G3: 2025.2Q | H3: =H4+H9 -> 695224
A4: KR0011 | B4: DB손보 | D4: 손해보험 | E4: =E3+1 -> 3 | F4: 생명장기 원수손익 | G4: 2025.2Q | H4: =보험손익!C22-보험손익!C55 -> 697862
A5: KR0011 | B5: DB손보 | D5: 손해보험 | E5: =E4+1 -> 4 | F5: 원수 CSM상각 | G5: 2025.2Q | H5: =보험손익!C20 -> 648936
A6: KR0011 | B6: DB손보 | D6: 손해보험 | E6: =E5+1 -> 5 | F6: 원수 위험조정 변동 | G6: 2025.2Q | H6: =보험손익!C19 -> 76237
A7: KR0011 | B7: DB손보 | D7: 손해보험 | E7: =E6+1 -> 6 | F7: 원수 예실차 | G7: 2025.2Q | H7: =보험손익!C14+보험손익!C16+보험손익!C17+보험손익!C18-보험손익!C44-보험손익!C47-보험손익!C48-보험손익!C49 -> 54770
A8: KR0011 | B8: DB손보 | D8: 손해보험 | E8: =E7+1 -> 7 | F8: 기타 생명장기 원수손익 | G8: 2025.2Q | H8: =H4-SUM(H5:H7) -> -82081
A9: KR0011 | B9: DB손보 | D9: 손해보험 | E9: =E8+1 -> 8 | F9: 생명장기 재보험손익 | G9: 2025.2Q | H9: =보험손익!C83-보험손익!C100 -> -2638
A10: KR0011 | B10: DB손보 | D10: 손해보험 | E10: =E9+1 -> 9 | F10: 재보험 CSM상각 | G10: 2025.2Q | H10: =-보험손익!C97 -> 1413
A11: KR0011 | B11: DB손보 | D11: 손해보험 | E11: =E10+1 -> 10 | F11: 재보험 위험조정 변동 | G11: 2025.2Q | H11: =-보험손익!C96 -> -2093
A12: KR0011 | B12: DB손보 | D12: 손해보험 | E12: =E11+1 -> 11 | F12: 재보험 예실차 | G12: 2025.2Q | H12: =보험손익!C77+보험손익!C78-보험손익!C94-보험손익!C95 -> -45549
A13: KR0011 | B13: DB손보 | D13: 손해보험 | E13: =E12+1 -> 12 | F13: 기타 생명장기 재보험손익 | G13: 2025.2Q | H13: =H9-SUM(H10:H12) -> 43591
A14: KR0011 | B14: DB손보 | D14: 손해보험 | E14: =E13+1 -> 13 | F14: 자동차손익 | G14: 2025.2Q | H14: =보험손익!O22+보험손익!AG22-보험손익!G55-보험손익!O55+보험손익!G83-보험손익!O100 -> 90130
A15: KR0011 | B15: DB손보 | D15: 손해보험 | E15: =E14+1 -> 14 | F15: 일반손익 | G15: 2025.2Q | H15: =보험손익!M22+보험손익!AE22-보험손익!E55-보험손익!M55+보험손익!E83-보험손익!M100 -> -48510
A16: KR0011 | B16: DB손보 | D16: 손해보험 | E16: =E15+1 -> 15 | F16: 기타영업수익 | G16: 2025.2Q
A17: KR0011 | B17: DB손보 | D17: 손해보험 | E17: =E16+1 -> 16 | F17: 기타사업비용 | G17: 2025.2Q | H17: 66432
A18: KR0011 | B18: DB손보 | D18: 손해보험 | E18: =E17+1 -> 17 | F18: 투자손익 | G18: 2025.2Q
A19: KR0011 | B19: DB손보 | D19: 손해보험 | E19: =E18+1 -> 18 | F19: 투자이익 | G19: 2025.2Q
A20: KR0011 | B20: DB손보 | D20: 손해보험 | E20: =E19+1 -> 19 | F20: 보험금융손익 | G20: 2025.2Q
A21: KR0011 | B21: DB손보 | D21: 손해보험 | E21: =E20+1 -> 20 | F21: 영업이익 | G21: 2025.2Q
A22: KR0011 | B22: DB손보 | D22: 손해보험 | E22: =E21+1 -> 21 | F22: 영업외손익 | G22: 2025.2Q
A23: KR0011 | B23: DB손보 | D23: 손해보험 | E23: =E22+1 -> 22 | F23: 세전이익 | G23: 2025.2Q
A24: KR0011 | B24: DB손보 | D24: 손해보험 | E24: =E23+1 -> 23 | F24: 법인세 | G24: 2025.2Q
A25: KR0011 | B25: DB손보 | D25: 손해보험 | E25: =E24+1 -> 24 | F25: 당기순이익 | G25: 2025.2Q

Sheet 보험손익
A1: 5. 보험수익 및 비용
A3: 발행보험의 보험수익 분석 공시
A4: 발행보험의 보험수익 분석 공시
A5: 당반기 | B5: (단위 : 백만원)
B6: 보험계약의 세분
B7: 발행한 보험계약
B8: 원수보험 | T8: 수재보험
B9: 보험계약 | R9: 보험계약 합계 | T9: 보험계약 | AJ9: 보험계약 합계
B10: 보험료배분접근법을 적용한 보험계약 외의 보험계약 | J10: 보험료배분접근법을 적용한 보험계약 | T10: 보험료배분접근법을 적용한 보험계약 외의 보험계약 | AB10: 보험료배분접근법을 적용한 보험계약
B11: 계약의 유형 | H11: 계약의 유형 합계 | J11: 계약의 유형 | P11: 계약의 유형 합계 | T11: 계약의 유형 | Z11: 계약의 유형 합계 | AB11: 계약의 유형 | AH11: 계약의 유형 합계
B12: 장기보험 | D12: 일반보험 | F12: 자동차보험 | J12: 장기보험 | L12: 일반보험 | N12: 자동차보험 | T12: 장기보험 | V12: 일반보험 | X12: 자동차보험 | AB12: 장기보험 | AD12: 일반보험 | AF12: 자동차보험
B13: 3개월 | C13: 누적 | D13: 3개월 | E13: 누적 | F13: 3개월 | G13: 누적 | H13: 3개월 | I13: 누적 | J13: 3개월 | K13: 누적 | L13: 3개월 | M13: 누적 | N13: 3개월 | O13: 누적 | P13: 3개월 | Q13: 누적 | R13: 3개월 | S13: 누적 | T13: 3개월 | U13: 누적 | V13: 3개월 | W13: 누적 | X13: 3개월 | Y13: 누적 | Z13: 3개월 | AA13: 누적 | AB13: 3개월 | AC13: 누적 | AD13: 3개월 | AE13: 누적 | AF13: 3개월 | AG13: 누적 | AH13: 3개월 | AI13: 누적 | AJ13: 3개월 | AK13: 누적
A14: 보험수익, 예상 보험금 (기초 예상 측정치) | B14: 1259901 | C14: 2510535 | D14: 0 | E14: 0 | F14: 0 | G14: 0 | R14: 1259901 | S14: 2510535
A15: 보험수익, 보험취득 현금흐름의 회수와 관련되는 보험료 부분의 배분액 | B15: 419663 | C15: 868276 | D15: 0 | E15: 0 | F15: 0 | G15: 0 | R15: 419663 | S15: 868276
A16: 보험수익, 예상 유지비 (기초 예상 측정치) | B16: 116325 | C16: 230991 | D16: 0 | E16: 0 | F16: 0 | G16: 0 | R16: 116325 | S16: 230991
A17: 보험수익, 예상 손해조사비 (기초 예상 측정치) | B17: 52804 | C17: 105766 | D17: 0 | E17: 0 | F17: 0 | G17: 0 | R17: 52804 | S17: 105766
A18: 보험수익, 예상 투자관리비 (기초 예상 측정치) | B18: 4226 | C18: 8415 | D18: 0 | E18: 0 | F18: 0 | G18: 0 | R18: 4226 | S18: 8415
A19: 보험수익, 비금융위험에 대한 위험조정의 변동분 | B19: 38192 | C19: 76237 | D19: 0 | E19: 0 | F19: 0 | G19: 0 | R19: 38192 | S19: 76237
A20: 보험수익, 서비스의 이전으로 당기손익에 인식한 보험계약마진 | B20: 326342 | C20: 648936 | D20: 0 | E20: 0 | F20: 0 | G20: 0 | R20: 326342 | S20: 648936
A21: 보험수익에 배분된 손실요소 | B21: -26933 | C21: -54674 | D21: 0 | E21: 0 | F21: 0 | G21: 0 | R21: -26933 | S21: -54674
A22: 보험수익 | B22: 2190520 | C22: 4394482 | D22: 0 | E22: 0 | F22: 0 | G22: 0 | H22: 0 | I22: 0 | J22: 0 | K22: 0 | L22: 547697 | M22: 1081536 | N22: 1019505 | O22: 2029860 | P22: 1567202 | Q22: 3111396 | R22: 3757722 | S22: 7505878 | AB22: 0 | AC22: 0 | AD22: 22147 | AE22: 50913 | AF22: 0 | AG22: 0 | AH22: 22147 | AI22: 50913 | AJ22: 22147 | AK22: 50913
A24: 발행보험의 보험수익 분석 공시, 합계 | C24: =C20-C97 -> 650349
A26: 발행보험의 보험수익 분석 공시, 합계
A27: 당반기 | B27: (단위 : 백만원)
B28: 보험계약의 세분
B29: 발행한 보험계약
B30: 계약의 유형 | H30: 계약의 유형 합계
B31: 장기보험 | D31: 일반보험 | F31: 자동차보험
B32: 3개월 | C32: 누적 | D32: 3개월 | E32: 누적 | F32: 3개월 | G32: 누적 | H32: 3개월 | I32: 누적
A33: 보험수익 | B33: 2190520 | C33: 4394482 | D33: 569844 | E33: 1132449 | F33: 1019505 | G33: 2029860 | H33: 3779869 | I33: 7556791
A36: 발행보험의 보험서비스비용 분석 공시
A37: 당반기 | B37: (단위 : 백만원)
B38: 보험계약의 세분
B39: 발행한 보험계약
B40: 원수보험 | J40: 수재보험
B41: 계약의 유형 | H41: 계약의 유형 합계 | J41: 계약의 유형 | P41: 계약의 유형 합계
B42: 장기보험 | D42: 일반보험 | F42: 자동차보험 | J42: 장기보험 | L42: 일반보험 | N42: 자동차보험
B43: 3개월 | C43: 누적 | D43: 3개월 | E43: 누적 | F43: 3개월 | G43: 누적 | H43: 3개월 | I43: 누적 | J43: 3개월 | K43: 누적 | L43: 3개월 | M43: 누적 | N43: 3개월 | O43: 누적 | P43: 3개월 | Q43: 누적
A44: 보험서비스비용, 발생한 보험금 | B44: 1218692 | C44: 2443900 | D44: 537762 | E44: 848129 | F44: 758839 | G44: 1499937 | H44: 2515293 | I44: 4791966 | J44: 0 | K44: 0 | L44: 106937 | M44: 224089 | N44: 0 | O44: 0 | P44: 106937 | Q44: 224089
A45: 보험취득현금흐름상각 | B45: 419663 | C45: 868276 | D45: 102139 | E45: 210228 | F45: 0 | G45: 0 | H45: 521802 | I45: 1078504
...
