Workbook

Sheet Sheet2
A1: 원보험사코드 | B1: 원수사명 | C1: 티커 | D1: 생손보여부 | E1: 항목번호 | F1: 항목명 | G1: 공시분기 | H1: 값 | I1: 검증
B2: 동양생명 | D2: 생명보험 | E2: 1 | F2: 보험손익 | G2: 2023.2Q | H2: =H3+H14+H15+H16-H17 -> 116208 | I2: =ROUND(H2,0)=ROUND(포괄손익계산서!C7/1000000,0) -> TRUE
B3: 동양생명 | D3: 생명보험 | E3: =E2+1 -> 2 | F3: 생명장기 손익 | G3: 2023.2Q | H3: =H4+H9 -> 128768
B4: 동양생명 | D4: 생명보험 | E4: =E3+1 -> 3 | F4: 생명장기 원수손익 | G4: 2023.2Q | H4: =부문별!C14-부문별!C23 -> 130035
B5: 동양생명 | D5: 생명보험 | E5: =E4+1 -> 4 | F5: 원수 CSM상각 | G5: 2023.2Q | H5: =부문별!C11 -> 127412
B6: 동양생명 | D6: 생명보험 | E6: =E5+1 -> 5 | F6: 원수 위험조정 변동 | G6: 2023.2Q | H6: =부문별!C10 -> 22438
B7: 동양생명 | D7: 생명보험 | E7: =E6+1 -> 6 | F7: 원수 예실차 | G7: 2023.2Q | H7: =부문별!C8+부문별!C9-부문별!C16-부문별!C17 -> 5817
B8: 동양생명 | D8: 생명보험 | E8: =E7+1 -> 7 | F8: 기타 생명장기 원수손익 | G8: 2023.2Q | H8: =H4-SUM(H5:H7) -> -25632
B9: 동양생명 | D9: 생명보험 | E9: =E8+1 -> 8 | F9: 생명장기 재보험손익 | G9: 2023.2Q | H9: =부문별!C25-부문별!C26 -> -1267
B10: 동양생명 | D10: 생명보험 | E10: =E9+1 -> 9 | F10: 재보험 CSM상각 | G10: 2023.2Q
B11: 동양생명 | D11: 생명보험 | E11: =E10+1 -> 10 | F11: 재보험 위험조정 변동 | G11: 2023.2Q
B12: 동양생명 | D12: 생명보험 | E12: =E11+1 -> 11 | F12: 재보험 예실차 | G12: 2023.2Q
B13: 동양생명 | D13: 생명보험 | E13: =E12+1 -> 12 | F13: 기타 생명장기 재보험손익 | G13: 2023.2Q
B14: 동양생명 | D14: 생명보험 | E14: =E13+1 -> 13 | F14: 자동차손익 | G14: 2023.2Q | H14: 0
B15: 동양생명 | D15: 생명보험 | E15: =E14+1 -> 14 | F15: 일반손익 | G15: 2023.2Q | H15: 0
B16: 동양생명 | D16: 생명보험 | E16: =E15+1 -> 15 | F16: 기타영업수익 | G16: 2023.2Q | H16: 0
B17: 동양생명 | D17: 생명보험 | E17: =E16+1 -> 16 | F17: 기타사업비용 | G17: 2023.2Q | H17: =부문별!C28 -> 12560
B18: 동양생명 | D18: 생명보험 | E18: =E17+1 -> 17 | F18: 투자손익 | G18: 2023.2Q | H18: =SUM(H19:H20) -> 133169.08
B19: 동양생명 | D19: 생명보험 | E19: =E18+1 -> 18 | F19: 투자이익 | G19: 2023.2Q | H19: =포괄손익계산서!C28/1000000 -> 699587.16
B20: 동양생명 | D20: 생명보험 | E20: =E19+1 -> 19 | F20: 보험금융손익 | G20: 2023.2Q | H20: =포괄손익계산서!C56/1000000 -> -566418.08
B21: 동양생명 | D21: 생명보험 | E21: =E20+1 -> 20 | F21: 영업이익 | G21: 2023.2Q | H21: =H2+H18 -> 249377.08 | I21: =ROUND(H21,0)=ROUND(포괄손익계산서!C59/1000000,0) -> TRUE
B22: 동양생명 | D22: 생명보험 | E22: =E21+1 -> 21 | F22: 영업외손익 | G22: 2023.2Q | H22: =(포괄손익계산서!C60-포괄손익계산서!C61)/1000000 -> 3071.8475
B23: 동양생명 | D23: 생명보험 | E23: =E22+1 -> 22 | F23: 세전이익 | G23: 2023.2Q | H23: =H21+H22 -> 252448.93 | I23: =ROUND(H23,0)=ROUND(포괄손익계산서!C62/1000000,0) -> TRUE
B24: 동양생명 | D24: 생명보험 | E24: =E23+1 -> 23 | F24: 법인세 | G24: 2023.2Q | H24: =포괄손익계산서!C63/1000000 -> 52199.378
B25: 동양생명 | D25: 생명보험 | E25: =E24+1 -> 24 | F25: 당기순이익 | G25: 2023.2Q | H25: =H23-H24 -> 200249.55 | I25: =ROUND(H25,0)=ROUND(포괄손익계산서!C64/1000000,0) -> TRUE

Sheet 부문별
A1: 22. 순보험손익
A2: 당반기와 전반기 중 순보험손익은 다음과 같습니다.
A3: (단위 : 백만원)
A4: 구분 | B4: 당반기 | D4: 전반기
B5: 3개월 | C5: 누적 | D5: 3개월 | E5: 누적
A6: 보험수익
A7: 보험료배분접근법 미적용 계약
A8: 예상 발생보험금 | B8: 129012 | C8: 255376 | D8: 119943 | E8: 237018
A9: 예상 기타보험서비스비용 | B9: 44118 | C9: 88416 | D9: 43996 | E9: 87434
A10: 위험조정 변동 | B10: 11156 | C10: 22438 | D10: 12396 | E10: 24949
A11: 제공된 서비스의 보험계약마진 | B11: 62557 | C11: 127412 | D11: 54568 | E11: 106764
A12: 보험취득현금흐름 회수 | B12: 27572 | C12: 56319 | D12: 21281 | E12: 41576
A13: 손실요소 배분액 | B13: -2963 | C13: -5895 | D13: -1116 | E13: -2331
A14: 총 보험수익 | B14: 271452 | C14: 544066 | D14: 251068 | E14: 495410
A15: 보험서비스비용
A16: 실제 발생보험금 | B16: 121450 | C16: 250993 | D16: 117965 | E16: 233742
A17: 실제 기타보험서비스비용 | B17: 44088 | C17: 86982 | D17: 40403 | E17: 78988
A18: 손실부담계약 인식 및 환입 | B18: 18925 | C18: 23999 | D18: -2455 | E18: -3588
A19: 발생사고부채 변동 | B19: 2188 | C19: 3454 | D19: 2142 | E19: 1487
A20: 보험취득현금흐름 상각 | B20: 27572 | C20: 56319 | D20: 21281 | E20: 41576
A21: 손실요소 배분액 | B21: -2963 | C21: -5895 | D21: -1116 | E21: -2331
A22: 기타영업비용 | B22: -2180 | C22: -1821 | D22: 166 | E22: 656
A23: 총 보험서비스비용 | B23: 209080 | C23: 414031 | D23: 178386 | E23: 350530
A24: 발행한 보험계약의 보험서비스결과 | B24: 62372 | C24: 130035 | D24: 72682 | E24: 144880
A25: 재보험수익 | B25: 4415 | C25: 11979 | D25: 4958 | E25: 9212
A26: 재보험비용 | B26: 5416 | C26: 13246 | D26: 5330 | E26: 8522
A27: 재보험계약의 보험서비스결과 | B27: -1001 | C27: -1267 | D27: -372 | E27: 690
... A29: 총 보험서비스결과 | B29: 55138 | C29: 116208 | D29: 65904 | E29: 133348

Sheet 포괄손익계산서
A1: 나. 포괄손익계산서
A2: 포 괄 손 익 계 산 서
A3: 제35기 2분기 (2023. 01. 01 ~ 2023. 6. 30)
A4: 제34기 2분기 (2022. 01. 01 ~ 2022. 6. 30)
A5: (단위 : 원)
A6: 과 목 | B6: 주석 | C6: 제35기 2분기 | D6: 제34기 2분기
A7: Ⅰ. 순보험서비스손익 | C7: 116208234746 | D7: 133346919160
A8: 1. 보험계약의 보험서비스결과 | B8: 14, 22 | C8: 130035128123 | D8: 144879481128
A9: (1) 보험수익 | C9: 544066551254 | D9: 495409620272
A10: 가. 예상 발생보험금 | C10: 255375928728 | D10: 237017725950 | F10: =SUM(C10:C11)-SUM(C17:C18) -> 5816358822
A11: 나. 예상 기타보험서비스비용 | C11: 88415907777 | D11: 87433693992
A12: 다. 위험조정 변동 | C12: 22438336230 | D12: 24948573679
A13: 라. 제공된 서비스의 보험계약마진 | C13: 127412368343 | D13: 106764371980
A14: 마. 보험취득현금흐름 회수 | C14: 56318593298 | D14: 41576393351
A15: 바. 손실요소 배분액 | C15: -5894583122 | D15: -2331138680
A16: (2) 보험서비스비용 | C16: 414031423131 | D16: 350530139144
A17: 가. 실제 발생보험금 | C17: 250993381654 | D17: 233741810676
A18: 나. 실제 기타보험서비스비용 | C18: 86982096029 | D18: 78988225703
A19: 다. 손실부담계약 인식 및 환입 | C19: 23999238371 | D19: -3588103504
A20: 라. 발생사고부채 변동 | C20: 3453969847 | D20: 1486663860
A21: 마. 보험취득현금흐름 상각 | C21: 56318593298 | D21: 41576393351
A22: 바. 손실요소 배분액 | C22: -5894583122 | D22: -2331138680
A23: 사. 기타영업비용 | C23: -1821272946 | D23: 656287738
A24: 2. 재보험계약의 보험서비스결과 | B24: 14, 22 | C24: -1266504931 | D24: 689271091
A25: (1) 재보험수익 | C25: 11979347570 | D25: 9211767412
A26: (2) 재보험비용 | C26: 13245852501 | D26: 8522496321
A27: 3. 기타보험비용 | B27: 14, 22 | C27: 12560388446 | D27: 12221833059
A28: Ⅱ. 순투자손익 | C28: 699587163908 | D28: 303552442503
A29: 1. 투자영업수익 | B29: 23, 24, 25, 26, 30 | C29: 1208422748699 | D29: 1144410184114
A30: (1) 이자수익 | C30: 446169266643 | D30: 418502265842
A31: (2) 배당수익 | C31: 520328481 | D31: 62496804181
A32: (3) 당기손익-공정가치측정금융자산관련이익 | C32: 351668121224 | D32: 0
A33: (4) 당기손익인식금융자산관련이익 | C33: 0 | D33: 47721696265
A34: (5) 기타포괄손익-공정가치측정금융자산관련이익 | C34: 1572626244 | D34: 0
A35: (6) 매도가능금융자산관련이익 | C35: 0 | D35: 46480735403
A36: (7) 상각후원가측정금융자산관련이익 | C36: 22412403 | D36: 0
A37: (8) 기대신용손실환입액 | C37: 0 | D37: 0
A38: (9) 손상차손환입 | C38: 0 | D38: 180461318
A39: (10) 외환거래이익 | B39: 13 | C39: 252552550977 | D39: 526128595344
A40: (11) 파생상품관련이익 | C40: 85995617960 | D40: 13729200772
...
